[2018-12-29 08:58:41,357][Thread-5:10072][task_id:django.server][basehttp.py:124][ERROR]["POST /user/login/ HTTP/1.1" 500 59]
[2018-12-29 09:29:19,335][Thread-1:11372][task_id:django.request][exception.py:118][ERROR][Internal Server Error: /project_management/pro_schedule/]
Traceback (most recent call last):
  File "C:\Python\lib\site-packages\django\core\handlers\exception.py", line 35, in inner
    response = get_response(request)
  File "C:\Python\lib\site-packages\django\core\handlers\base.py", line 128, in _get_response
    response = self.process_exception_by_middleware(e, request)
  File "C:\Python\lib\site-packages\django\core\handlers\base.py", line 126, in _get_response
    response = wrapped_callback(request, *callback_args, **callback_kwargs)
  File "C:\Python\lib\site-packages\django\views\generic\base.py", line 69, in view
    return self.dispatch(request, *args, **kwargs)
  File "C:\Python\lib\site-packages\django\views\generic\base.py", line 89, in dispatch
    return handler(request, *args, **kwargs)
  File "C:\Python\bank\project_management\views.py", line 91, in get
    pro_dateils = Pro_dateils_shiji.objects.filter(project_sj_id=id).all()
  File "C:\Python\lib\site-packages\django\db\models\manager.py", line 82, in manager_method
    return getattr(self.get_queryset(), name)(*args, **kwargs)
  File "C:\Python\lib\site-packages\django\db\models\query.py", line 836, in filter
    return self._filter_or_exclude(False, *args, **kwargs)
  File "C:\Python\lib\site-packages\django\db\models\query.py", line 854, in _filter_or_exclude
    clone.query.add_q(Q(*args, **kwargs))
  File "C:\Python\lib\site-packages\django\db\models\sql\query.py", line 1252, in add_q
    clause, _ = self._add_q(q_object, self.used_aliases)
  File "C:\Python\lib\site-packages\django\db\models\sql\query.py", line 1276, in _add_q
    split_subq=split_subq,
  File "C:\Python\lib\site-packages\django\db\models\sql\query.py", line 1214, in build_filter
    condition = self.build_lookup(lookups, col, value)
  File "C:\Python\lib\site-packages\django\db\models\sql\query.py", line 1084, in build_lookup
    lookup = lookup_class(lhs, rhs)
  File "C:\Python\lib\site-packages\django\db\models\lookups.py", line 18, in __init__
    self.rhs = self.get_prep_lookup()
  File "C:\Python\lib\site-packages\django\db\models\fields\related_lookups.py", line 115, in get_prep_lookup
    self.rhs = target_field.get_prep_value(self.rhs)
  File "C:\Python\lib\site-packages\django\db\models\fields\__init__.py", line 947, in get_prep_value
    return int(value)
ValueError: invalid literal for int() with base 10: ''
[2018-12-29 09:29:19,860][Thread-1:11372][task_id:django.server][basehttp.py:124][ERROR]["GET /project_management/pro_schedule/?id= HTTP/1.1" 500 126474]
[2018-12-29 09:32:58,683][Thread-6:8988][task_id:django.request][exception.py:118][ERROR][Internal Server Error: /project_management/pro_schedule/]
Traceback (most recent call last):
  File "C:\Python\lib\site-packages\django\core\handlers\exception.py", line 35, in inner
    response = get_response(request)
  File "C:\Python\lib\site-packages\django\core\handlers\base.py", line 128, in _get_response
    response = self.process_exception_by_middleware(e, request)
  File "C:\Python\lib\site-packages\django\core\handlers\base.py", line 126, in _get_response
    response = wrapped_callback(request, *callback_args, **callback_kwargs)
  File "C:\Python\lib\site-packages\django\views\generic\base.py", line 69, in view
    return self.dispatch(request, *args, **kwargs)
  File "C:\Python\lib\site-packages\django\views\generic\base.py", line 89, in dispatch
    return handler(request, *args, **kwargs)
  File "C:\Python\bank\project_management\views.py", line 91, in get
    pro_dateils = Pro_dateils_shiji.objects.filter(project_sj_id=id).all()
  File "C:\Python\lib\site-packages\django\db\models\manager.py", line 82, in manager_method
    return getattr(self.get_queryset(), name)(*args, **kwargs)
  File "C:\Python\lib\site-packages\django\db\models\query.py", line 836, in filter
    return self._filter_or_exclude(False, *args, **kwargs)
  File "C:\Python\lib\site-packages\django\db\models\query.py", line 854, in _filter_or_exclude
    clone.query.add_q(Q(*args, **kwargs))
  File "C:\Python\lib\site-packages\django\db\models\sql\query.py", line 1252, in add_q
    clause, _ = self._add_q(q_object, self.used_aliases)
  File "C:\Python\lib\site-packages\django\db\models\sql\query.py", line 1276, in _add_q
    split_subq=split_subq,
  File "C:\Python\lib\site-packages\django\db\models\sql\query.py", line 1214, in build_filter
    condition = self.build_lookup(lookups, col, value)
  File "C:\Python\lib\site-packages\django\db\models\sql\query.py", line 1084, in build_lookup
    lookup = lookup_class(lhs, rhs)
  File "C:\Python\lib\site-packages\django\db\models\lookups.py", line 18, in __init__
    self.rhs = self.get_prep_lookup()
  File "C:\Python\lib\site-packages\django\db\models\fields\related_lookups.py", line 115, in get_prep_lookup
    self.rhs = target_field.get_prep_value(self.rhs)
  File "C:\Python\lib\site-packages\django\db\models\fields\__init__.py", line 947, in get_prep_value
    return int(value)
ValueError: invalid literal for int() with base 10: ''
[2018-12-29 09:32:59,034][Thread-6:8988][task_id:django.server][basehttp.py:124][ERROR]["GET /project_management/pro_schedule/?id= HTTP/1.1" 500 126316]
[2018-12-29 09:34:48,329][Thread-5:9528][task_id:django.request][exception.py:118][ERROR][Internal Server Error: /project_management/pro_schedule/]
Traceback (most recent call last):
  File "C:\Python\lib\site-packages\django\core\handlers\exception.py", line 35, in inner
    response = get_response(request)
  File "C:\Python\lib\site-packages\django\core\handlers\base.py", line 128, in _get_response
    response = self.process_exception_by_middleware(e, request)
  File "C:\Python\lib\site-packages\django\core\handlers\base.py", line 126, in _get_response
    response = wrapped_callback(request, *callback_args, **callback_kwargs)
  File "C:\Python\lib\site-packages\django\views\generic\base.py", line 69, in view
    return self.dispatch(request, *args, **kwargs)
  File "C:\Python\lib\site-packages\django\views\generic\base.py", line 89, in dispatch
    return handler(request, *args, **kwargs)
  File "C:\Python\bank\project_management\views.py", line 91, in get
    pro_dateils = Pro_dateils_shiji.objects.filter(project_sj_id=id).all()
  File "C:\Python\lib\site-packages\django\db\models\manager.py", line 82, in manager_method
    return getattr(self.get_queryset(), name)(*args, **kwargs)
  File "C:\Python\lib\site-packages\django\db\models\query.py", line 836, in filter
    return self._filter_or_exclude(False, *args, **kwargs)
  File "C:\Python\lib\site-packages\django\db\models\query.py", line 854, in _filter_or_exclude
    clone.query.add_q(Q(*args, **kwargs))
  File "C:\Python\lib\site-packages\django\db\models\sql\query.py", line 1252, in add_q
    clause, _ = self._add_q(q_object, self.used_aliases)
  File "C:\Python\lib\site-packages\django\db\models\sql\query.py", line 1276, in _add_q
    split_subq=split_subq,
  File "C:\Python\lib\site-packages\django\db\models\sql\query.py", line 1214, in build_filter
    condition = self.build_lookup(lookups, col, value)
  File "C:\Python\lib\site-packages\django\db\models\sql\query.py", line 1084, in build_lookup
    lookup = lookup_class(lhs, rhs)
  File "C:\Python\lib\site-packages\django\db\models\lookups.py", line 18, in __init__
    self.rhs = self.get_prep_lookup()
  File "C:\Python\lib\site-packages\django\db\models\fields\related_lookups.py", line 115, in get_prep_lookup
    self.rhs = target_field.get_prep_value(self.rhs)
  File "C:\Python\lib\site-packages\django\db\models\fields\__init__.py", line 947, in get_prep_value
    return int(value)
ValueError: invalid literal for int() with base 10: ''
[2018-12-29 09:34:48,658][Thread-5:9528][task_id:django.server][basehttp.py:124][ERROR]["GET /project_management/pro_schedule/?id= HTTP/1.1" 500 126335]
[2018-12-29 09:35:22,596][Thread-8:3056][task_id:django.request][exception.py:118][ERROR][Internal Server Error: /project_management/pro_schedule/]
Traceback (most recent call last):
  File "C:\Python\lib\site-packages\django\core\handlers\exception.py", line 35, in inner
    response = get_response(request)
  File "C:\Python\lib\site-packages\django\core\handlers\base.py", line 128, in _get_response
    response = self.process_exception_by_middleware(e, request)
  File "C:\Python\lib\site-packages\django\core\handlers\base.py", line 126, in _get_response
    response = wrapped_callback(request, *callback_args, **callback_kwargs)
  File "C:\Python\lib\site-packages\django\views\generic\base.py", line 69, in view
    return self.dispatch(request, *args, **kwargs)
  File "C:\Python\lib\site-packages\django\views\generic\base.py", line 89, in dispatch
    return handler(request, *args, **kwargs)
  File "C:\Python\bank\project_management\views.py", line 91, in get
    pro_dateils = Pro_dateils_shiji.objects.filter(project_sj_id=id).all()
  File "C:\Python\lib\site-packages\django\db\models\manager.py", line 82, in manager_method
    return getattr(self.get_queryset(), name)(*args, **kwargs)
  File "C:\Python\lib\site-packages\django\db\models\query.py", line 836, in filter
    return self._filter_or_exclude(False, *args, **kwargs)
  File "C:\Python\lib\site-packages\django\db\models\query.py", line 854, in _filter_or_exclude
    clone.query.add_q(Q(*args, **kwargs))
  File "C:\Python\lib\site-packages\django\db\models\sql\query.py", line 1252, in add_q
    clause, _ = self._add_q(q_object, self.used_aliases)
  File "C:\Python\lib\site-packages\django\db\models\sql\query.py", line 1276, in _add_q
    split_subq=split_subq,
  File "C:\Python\lib\site-packages\django\db\models\sql\query.py", line 1214, in build_filter
    condition = self.build_lookup(lookups, col, value)
  File "C:\Python\lib\site-packages\django\db\models\sql\query.py", line 1084, in build_lookup
    lookup = lookup_class(lhs, rhs)
  File "C:\Python\lib\site-packages\django\db\models\lookups.py", line 18, in __init__
    self.rhs = self.get_prep_lookup()
  File "C:\Python\lib\site-packages\django\db\models\fields\related_lookups.py", line 115, in get_prep_lookup
    self.rhs = target_field.get_prep_value(self.rhs)
  File "C:\Python\lib\site-packages\django\db\models\fields\__init__.py", line 947, in get_prep_value
    return int(value)
ValueError: invalid literal for int() with base 10: ''
[2018-12-29 09:35:22,693][Thread-8:3056][task_id:django.server][basehttp.py:124][ERROR]["GET /project_management/pro_schedule/?id= HTTP/1.1" 500 126335]
[2018-12-29 09:39:12,166][Thread-5:4100][task_id:django.request][exception.py:118][ERROR][Internal Server Error: /project_management/pro_schedule/]
Traceback (most recent call last):
  File "C:\Python\lib\site-packages\django\core\handlers\exception.py", line 35, in inner
    response = get_response(request)
  File "C:\Python\lib\site-packages\django\core\handlers\base.py", line 128, in _get_response
    response = self.process_exception_by_middleware(e, request)
  File "C:\Python\lib\site-packages\django\core\handlers\base.py", line 126, in _get_response
    response = wrapped_callback(request, *callback_args, **callback_kwargs)
  File "C:\Python\lib\site-packages\django\views\generic\base.py", line 69, in view
    return self.dispatch(request, *args, **kwargs)
  File "C:\Python\lib\site-packages\django\views\generic\base.py", line 89, in dispatch
    return handler(request, *args, **kwargs)
  File "C:\Python\bank\project_management\views.py", line 96, in get
    start_time = int(time.mktime(time.strftime(i.pro_start_time, "%Y-%m-%d %H:%M:%S")))
TypeError: strftime() argument 1 must be str, not datetime.date
[2018-12-29 09:39:12,439][Thread-5:4100][task_id:django.server][basehttp.py:124][ERROR]["GET /project_management/pro_schedule/?id=1 HTTP/1.1" 500 79000]
[2018-12-29 09:42:15,998][Thread-5:2888][task_id:django.request][exception.py:118][ERROR][Internal Server Error: /project_management/pro_schedule/]
Traceback (most recent call last):
  File "C:\Python\lib\site-packages\django\core\handlers\exception.py", line 35, in inner
    response = get_response(request)
  File "C:\Python\lib\site-packages\django\core\handlers\base.py", line 128, in _get_response
    response = self.process_exception_by_middleware(e, request)
  File "C:\Python\lib\site-packages\django\core\handlers\base.py", line 126, in _get_response
    response = wrapped_callback(request, *callback_args, **callback_kwargs)
  File "C:\Python\lib\site-packages\django\views\generic\base.py", line 69, in view
    return self.dispatch(request, *args, **kwargs)
  File "C:\Python\lib\site-packages\django\views\generic\base.py", line 89, in dispatch
    return handler(request, *args, **kwargs)
  File "C:\Python\bank\project_management\views.py", line 97, in get
    start_time = int(time.mktime(time.strftime(str(i.pro_start_time), "%Y-%m-%d %H:%M:%S")))
TypeError: Tuple or struct_time argument required
[2018-12-29 09:42:16,320][Thread-5:2888][task_id:django.server][basehttp.py:124][ERROR]["GET /project_management/pro_schedule/?id=1 HTTP/1.1" 500 78990]
[2018-12-29 09:43:48,780][Thread-5:11996][task_id:django.request][exception.py:118][ERROR][Internal Server Error: /project_management/pro_schedule/]
Traceback (most recent call last):
  File "C:\Python\lib\site-packages\django\core\handlers\exception.py", line 35, in inner
    response = get_response(request)
  File "C:\Python\lib\site-packages\django\core\handlers\base.py", line 128, in _get_response
    response = self.process_exception_by_middleware(e, request)
  File "C:\Python\lib\site-packages\django\core\handlers\base.py", line 126, in _get_response
    response = wrapped_callback(request, *callback_args, **callback_kwargs)
  File "C:\Python\lib\site-packages\django\views\generic\base.py", line 69, in view
    return self.dispatch(request, *args, **kwargs)
  File "C:\Python\lib\site-packages\django\views\generic\base.py", line 89, in dispatch
    return handler(request, *args, **kwargs)
  File "C:\Python\bank\project_management\views.py", line 97, in get
    start_time = int(time.mktime(time.strftime(str(i.pro_start_time[0]), "%Y-%m-%d %H:%M:%S")))
TypeError: 'datetime.date' object is not subscriptable
[2018-12-29 09:43:49,062][Thread-5:11996][task_id:django.server][basehttp.py:124][ERROR]["GET /project_management/pro_schedule/?id=1 HTTP/1.1" 500 79049]
[2018-12-29 09:49:57,549][Thread-7:6776][task_id:django.request][exception.py:118][ERROR][Internal Server Error: /project_management/pro_schedule/]
Traceback (most recent call last):
  File "C:\Python\lib\site-packages\django\core\handlers\exception.py", line 35, in inner
    response = get_response(request)
  File "C:\Python\lib\site-packages\django\core\handlers\base.py", line 128, in _get_response
    response = self.process_exception_by_middleware(e, request)
  File "C:\Python\lib\site-packages\django\core\handlers\base.py", line 126, in _get_response
    response = wrapped_callback(request, *callback_args, **callback_kwargs)
  File "C:\Python\lib\site-packages\django\views\generic\base.py", line 69, in view
    return self.dispatch(request, *args, **kwargs)
  File "C:\Python\lib\site-packages\django\views\generic\base.py", line 89, in dispatch
    return handler(request, *args, **kwargs)
  File "C:\Python\bank\project_management\views.py", line 97, in get
    start_time = int(time.mktime((i.pro_start_time)))
TypeError: Tuple or struct_time argument required
[2018-12-29 09:49:57,870][Thread-7:6776][task_id:django.server][basehttp.py:124][ERROR]["GET /project_management/pro_schedule/?id=1 HTTP/1.1" 500 78892]
[2018-12-29 09:53:21,743][Thread-3:2108][task_id:django.request][exception.py:118][ERROR][Internal Server Error: /project_management/pro_schedule/]
Traceback (most recent call last):
  File "C:\Python\lib\site-packages\django\core\handlers\exception.py", line 35, in inner
    response = get_response(request)
  File "C:\Python\lib\site-packages\django\core\handlers\base.py", line 128, in _get_response
    response = self.process_exception_by_middleware(e, request)
  File "C:\Python\lib\site-packages\django\core\handlers\base.py", line 126, in _get_response
    response = wrapped_callback(request, *callback_args, **callback_kwargs)
  File "C:\Python\lib\site-packages\django\views\generic\base.py", line 69, in view
    return self.dispatch(request, *args, **kwargs)
  File "C:\Python\lib\site-packages\django\views\generic\base.py", line 89, in dispatch
    return handler(request, *args, **kwargs)
  File "C:\Python\bank\project_management\views.py", line 98, in get
    start_time = int(time.mktime((i.pro_start_time)))
TypeError: Tuple or struct_time argument required
[2018-12-29 09:53:22,034][Thread-3:2108][task_id:django.server][basehttp.py:124][ERROR]["GET /project_management/pro_schedule/?id=1 HTTP/1.1" 500 78840]
[2018-12-29 09:59:08,198][Thread-5:7512][task_id:django.request][exception.py:118][ERROR][Internal Server Error: /project_management/pro_schedule/]
Traceback (most recent call last):
  File "C:\Python\lib\site-packages\django\core\handlers\exception.py", line 35, in inner
    response = get_response(request)
  File "C:\Python\lib\site-packages\django\core\handlers\base.py", line 128, in _get_response
    response = self.process_exception_by_middleware(e, request)
  File "C:\Python\lib\site-packages\django\core\handlers\base.py", line 126, in _get_response
    response = wrapped_callback(request, *callback_args, **callback_kwargs)
  File "C:\Python\lib\site-packages\django\views\generic\base.py", line 69, in view
    return self.dispatch(request, *args, **kwargs)
  File "C:\Python\lib\site-packages\django\views\generic\base.py", line 89, in dispatch
    return handler(request, *args, **kwargs)
  File "C:\Python\bank\project_management\views.py", line 98, in get
    start_time =  int(time.mktime(time.strptime(i.pro_start_time, "%Y-%m-%d")))
  File "C:\Python\lib\_strptime.py", line 559, in _strptime_time
    tt = _strptime(data_string, format)[0]
  File "C:\Python\lib\_strptime.py", line 329, in _strptime
    raise TypeError(msg.format(index, type(arg)))
TypeError: strptime() argument 0 must be str, not <class 'datetime.date'>
[2018-12-29 09:59:08,543][Thread-5:7512][task_id:django.server][basehttp.py:124][ERROR]["GET /project_management/pro_schedule/?id=1 HTTP/1.1" 500 87232]
[2018-12-29 10:07:17,722][Thread-6:7476][task_id:django.request][exception.py:118][ERROR][Internal Server Error: /project_management/pro_schedule/]
Traceback (most recent call last):
  File "C:\Python\lib\site-packages\django\core\handlers\exception.py", line 35, in inner
    response = get_response(request)
  File "C:\Python\lib\site-packages\django\core\handlers\base.py", line 128, in _get_response
    response = self.process_exception_by_middleware(e, request)
  File "C:\Python\lib\site-packages\django\core\handlers\base.py", line 126, in _get_response
    response = wrapped_callback(request, *callback_args, **callback_kwargs)
  File "C:\Python\lib\site-packages\django\views\generic\base.py", line 69, in view
    return self.dispatch(request, *args, **kwargs)
  File "C:\Python\lib\site-packages\django\views\generic\base.py", line 89, in dispatch
    return handler(request, *args, **kwargs)
  File "C:\Python\bank\project_management\views.py", line 103, in get
    return render(request, 'project_schedule.html', locals())
  File "C:\Python\lib\site-packages\django\shortcuts.py", line 36, in render
    content = loader.render_to_string(template_name, context, request, using=using)
  File "C:\Python\lib\site-packages\django\template\loader.py", line 61, in render_to_string
    template = get_template(template_name, using=using)
  File "C:\Python\lib\site-packages\django\template\loader.py", line 15, in get_template
    return engine.get_template(template_name)
  File "C:\Python\lib\site-packages\django\template\backends\django.py", line 34, in get_template
    return Template(self.engine.get_template(template_name), self)
  File "C:\Python\lib\site-packages\django\template\engine.py", line 144, in get_template
    template, origin = self.find_template(template_name)
  File "C:\Python\lib\site-packages\django\template\engine.py", line 126, in find_template
    template = loader.get_template(name, skip=skip)
  File "C:\Python\lib\site-packages\django\template\loaders\base.py", line 30, in get_template
    contents, origin, origin.template_name, self.engine,
  File "C:\Python\lib\site-packages\django\template\base.py", line 160, in __init__
    self.nodelist = self.compile_nodelist()
  File "C:\Python\lib\site-packages\django\template\base.py", line 198, in compile_nodelist
    return parser.parse()
  File "C:\Python\lib\site-packages\django\template\base.py", line 483, in parse
    raise self.error(token, e)
  File "C:\Python\lib\site-packages\django\template\base.py", line 481, in parse
    compiled_result = compile_func(self, token)
  File "C:\Python\lib\site-packages\django\template\loader_tags.py", line 290, in do_extends
    nodelist = parser.parse()
  File "C:\Python\lib\site-packages\django\template\base.py", line 483, in parse
    raise self.error(token, e)
  File "C:\Python\lib\site-packages\django\template\base.py", line 481, in parse
    compiled_result = compile_func(self, token)
  File "C:\Python\lib\site-packages\django\template\loader_tags.py", line 233, in do_block
    nodelist = parser.parse(('endblock',))
  File "C:\Python\lib\site-packages\django\template\base.py", line 454, in parse
    raise self.error(token, e)
  File "C:\Python\lib\site-packages\django\template\base.py", line 452, in parse
    filter_expression = self.compile_filter(token.contents)
  File "C:\Python\lib\site-packages\django\template\base.py", line 568, in compile_filter
    return FilterExpression(token, self)
  File "C:\Python\lib\site-packages\django\template\base.py", line 668, in __init__
    "from '%s'" % (token[upto:], token))
django.template.exceptions.TemplateSyntaxError: Could not parse the remainder: '-1' from 'day_list.-1'
[2018-12-29 10:07:18,188][Thread-6:7476][task_id:django.server][basehttp.py:124][ERROR]["GET /project_management/pro_schedule/?id=1 HTTP/1.1" 500 179952]
[2018-12-29 10:38:36,020][Thread-4:5176][task_id:django.request][exception.py:118][ERROR][Internal Server Error: /project_management/pro_schedule/]
Traceback (most recent call last):
  File "C:\Python\lib\site-packages\django\core\handlers\exception.py", line 35, in inner
    response = get_response(request)
  File "C:\Python\lib\site-packages\django\core\handlers\base.py", line 128, in _get_response
    response = self.process_exception_by_middleware(e, request)
  File "C:\Python\lib\site-packages\django\core\handlers\base.py", line 126, in _get_response
    response = wrapped_callback(request, *callback_args, **callback_kwargs)
  File "C:\Python\lib\site-packages\django\views\generic\base.py", line 69, in view
    return self.dispatch(request, *args, **kwargs)
  File "C:\Python\lib\site-packages\django\views\generic\base.py", line 89, in dispatch
    return handler(request, *args, **kwargs)
  File "C:\Python\bank\project_management\views.py", line 113, in get
    return render(request, 'project_schedule.html', locals())
  File "C:\Python\lib\site-packages\django\shortcuts.py", line 36, in render
    content = loader.render_to_string(template_name, context, request, using=using)
  File "C:\Python\lib\site-packages\django\template\loader.py", line 61, in render_to_string
    template = get_template(template_name, using=using)
  File "C:\Python\lib\site-packages\django\template\loader.py", line 15, in get_template
    return engine.get_template(template_name)
  File "C:\Python\lib\site-packages\django\template\backends\django.py", line 34, in get_template
    return Template(self.engine.get_template(template_name), self)
  File "C:\Python\lib\site-packages\django\template\engine.py", line 144, in get_template
    template, origin = self.find_template(template_name)
  File "C:\Python\lib\site-packages\django\template\engine.py", line 126, in find_template
    template = loader.get_template(name, skip=skip)
  File "C:\Python\lib\site-packages\django\template\loaders\base.py", line 30, in get_template
    contents, origin, origin.template_name, self.engine,
  File "C:\Python\lib\site-packages\django\template\base.py", line 160, in __init__
    self.nodelist = self.compile_nodelist()
  File "C:\Python\lib\site-packages\django\template\base.py", line 198, in compile_nodelist
    return parser.parse()
  File "C:\Python\lib\site-packages\django\template\base.py", line 483, in parse
    raise self.error(token, e)
  File "C:\Python\lib\site-packages\django\template\base.py", line 481, in parse
    compiled_result = compile_func(self, token)
  File "C:\Python\lib\site-packages\django\template\loader_tags.py", line 290, in do_extends
    nodelist = parser.parse()
  File "C:\Python\lib\site-packages\django\template\base.py", line 483, in parse
    raise self.error(token, e)
  File "C:\Python\lib\site-packages\django\template\base.py", line 481, in parse
    compiled_result = compile_func(self, token)
  File "C:\Python\lib\site-packages\django\template\loader_tags.py", line 233, in do_block
    nodelist = parser.parse(('endblock',))
  File "C:\Python\lib\site-packages\django\template\base.py", line 450, in parse
    raise self.error(token, 'Empty variable tag on line %d' % token.lineno)
django.template.exceptions.TemplateSyntaxError: Empty variable tag on line 69
[2018-12-29 10:38:36,388][Thread-4:5176][task_id:django.server][basehttp.py:124][ERROR]["GET /project_management/pro_schedule/?id=1 HTTP/1.1" 500 166898]
[2018-12-29 10:39:15,303][Thread-11:1072][task_id:django.request][exception.py:118][ERROR][Internal Server Error: /project_management/add_project_stage/]
Traceback (most recent call last):
  File "C:\Python\lib\site-packages\django\core\handlers\exception.py", line 35, in inner
    response = get_response(request)
  File "C:\Python\lib\site-packages\django\core\handlers\base.py", line 128, in _get_response
    response = self.process_exception_by_middleware(e, request)
  File "C:\Python\lib\site-packages\django\core\handlers\base.py", line 126, in _get_response
    response = wrapped_callback(request, *callback_args, **callback_kwargs)
  File "C:\Python\lib\site-packages\django\views\generic\base.py", line 69, in view
    return self.dispatch(request, *args, **kwargs)
  File "C:\Python\lib\site-packages\django\views\generic\base.py", line 89, in dispatch
    return handler(request, *args, **kwargs)
  File "C:\Python\bank\project_management\views.py", line 192, in post
    p_name = Project.objects.filter(id=project_id).first().p_name # 项目名称
AttributeError: 'NoneType' object has no attribute 'p_name'
[2018-12-29 10:39:15,456][Thread-11:1072][task_id:django.server][basehttp.py:124][ERROR]["POST /project_management/add_project_stage/ HTTP/1.1" 500 80064]
[2018-12-29 15:56:23,701][Thread-5:12496][task_id:django.request][exception.py:118][ERROR][Internal Server Error: /project_management/pro_schedule/]
Traceback (most recent call last):
  File "C:\Python\lib\site-packages\django\core\handlers\exception.py", line 35, in inner
    response = get_response(request)
  File "C:\Python\lib\site-packages\django\core\handlers\base.py", line 128, in _get_response
    response = self.process_exception_by_middleware(e, request)
  File "C:\Python\lib\site-packages\django\core\handlers\base.py", line 126, in _get_response
    response = wrapped_callback(request, *callback_args, **callback_kwargs)
  File "C:\Python\lib\site-packages\django\views\generic\base.py", line 69, in view
    return self.dispatch(request, *args, **kwargs)
  File "C:\Python\lib\site-packages\django\views\generic\base.py", line 89, in dispatch
    return handler(request, *args, **kwargs)
  File "C:\Python\bank\project_management\views.py", line 102, in get
    start_time_jh =  int(time.mktime(time.strptime(str(i.pro_start_time_jh), "%Y-%m-%d")))
  File "C:\Python\lib\_strptime.py", line 559, in _strptime_time
    tt = _strptime(data_string, format)[0]
  File "C:\Python\lib\_strptime.py", line 362, in _strptime
    (data_string, format))
ValueError: time data 'None' does not match format '%Y-%m-%d'
[2018-12-29 15:56:24,736][Thread-5:12496][task_id:django.server][basehttp.py:124][ERROR]["GET /project_management/pro_schedule/?id=1 HTTP/1.1" 500 88737]
[2018-12-29 16:40:40,760][Thread-23:4396][task_id:django.request][exception.py:118][ERROR][Internal Server Error: /project_management/add_project_stage/]
Traceback (most recent call last):
  File "C:\Python\lib\site-packages\django\core\handlers\exception.py", line 35, in inner
    response = get_response(request)
  File "C:\Python\lib\site-packages\django\core\handlers\base.py", line 128, in _get_response
    response = self.process_exception_by_middleware(e, request)
  File "C:\Python\lib\site-packages\django\core\handlers\base.py", line 126, in _get_response
    response = wrapped_callback(request, *callback_args, **callback_kwargs)
  File "C:\Python\lib\site-packages\django\views\generic\base.py", line 69, in view
    return self.dispatch(request, *args, **kwargs)
  File "C:\Python\lib\site-packages\django\views\generic\base.py", line 89, in dispatch
    return handler(request, *args, **kwargs)
  File "C:\Python\bank\project_management\views.py", line 217, in post
    p_name = Project.objects.filter(id=project_id).first().p_name # 项目名称
AttributeError: 'NoneType' object has no attribute 'p_name'
[2018-12-29 16:40:40,878][Thread-23:4396][task_id:django.server][basehttp.py:124][ERROR]["POST /project_management/add_project_stage/ HTTP/1.1" 500 80420]
[2018-12-29 16:41:59,661][Thread-25:10720][task_id:django.request][exception.py:118][ERROR][Internal Server Error: /project_management/add_project_stage/]
Traceback (most recent call last):
  File "C:\Python\lib\site-packages\django\core\handlers\exception.py", line 35, in inner
    response = get_response(request)
  File "C:\Python\lib\site-packages\django\core\handlers\base.py", line 128, in _get_response
    response = self.process_exception_by_middleware(e, request)
  File "C:\Python\lib\site-packages\django\core\handlers\base.py", line 126, in _get_response
    response = wrapped_callback(request, *callback_args, **callback_kwargs)
  File "C:\Python\lib\site-packages\django\views\generic\base.py", line 69, in view
    return self.dispatch(request, *args, **kwargs)
  File "C:\Python\lib\site-packages\django\views\generic\base.py", line 89, in dispatch
    return handler(request, *args, **kwargs)
  File "C:\Python\bank\project_management\views.py", line 217, in post
    p_name = Project.objects.filter(id=project_id).first().p_name # 项目名称
AttributeError: 'NoneType' object has no attribute 'p_name'
[2018-12-29 16:41:59,709][Thread-25:10720][task_id:django.server][basehttp.py:124][ERROR]["POST /project_management/add_project_stage/ HTTP/1.1" 500 80420]
[2018-12-29 16:46:53,855][Thread-29:3068][task_id:django.request][exception.py:118][ERROR][Internal Server Error: /project_management/add_project_stage/]
Traceback (most recent call last):
  File "C:\Python\lib\site-packages\django\core\handlers\exception.py", line 35, in inner
    response = get_response(request)
  File "C:\Python\lib\site-packages\django\core\handlers\base.py", line 128, in _get_response
    response = self.process_exception_by_middleware(e, request)
  File "C:\Python\lib\site-packages\django\core\handlers\base.py", line 126, in _get_response
    response = wrapped_callback(request, *callback_args, **callback_kwargs)
  File "C:\Python\lib\site-packages\django\views\generic\base.py", line 69, in view
    return self.dispatch(request, *args, **kwargs)
  File "C:\Python\lib\site-packages\django\views\generic\base.py", line 89, in dispatch
    return handler(request, *args, **kwargs)
  File "C:\Python\bank\project_management\views.py", line 217, in post
    p_name = Project.objects.filter(id=project_id).first().p_name # 项目名称
AttributeError: 'NoneType' object has no attribute 'p_name'
[2018-12-29 16:46:53,901][Thread-29:3068][task_id:django.server][basehttp.py:124][ERROR]["POST /project_management/add_project_stage/ HTTP/1.1" 500 80420]
[2018-12-29 16:49:34,963][Thread-41:14076][task_id:django.request][exception.py:118][ERROR][Internal Server Error: /project_management/add_project_stage/]
Traceback (most recent call last):
  File "C:\Python\lib\site-packages\django\core\handlers\exception.py", line 35, in inner
    response = get_response(request)
  File "C:\Python\lib\site-packages\django\core\handlers\base.py", line 128, in _get_response
    response = self.process_exception_by_middleware(e, request)
  File "C:\Python\lib\site-packages\django\core\handlers\base.py", line 126, in _get_response
    response = wrapped_callback(request, *callback_args, **callback_kwargs)
  File "C:\Python\lib\site-packages\django\views\generic\base.py", line 69, in view
    return self.dispatch(request, *args, **kwargs)
  File "C:\Python\lib\site-packages\django\views\generic\base.py", line 89, in dispatch
    return handler(request, *args, **kwargs)
  File "C:\Python\bank\project_management\views.py", line 217, in post
    p_name = Project.objects.filter(id=project_id).first().p_name # 项目名称
AttributeError: 'NoneType' object has no attribute 'p_name'
[2018-12-29 16:49:35,009][Thread-41:14076][task_id:django.server][basehttp.py:124][ERROR]["POST /project_management/add_project_stage/ HTTP/1.1" 500 80420]
[2018-12-29 16:50:55,215][Thread-43:12508][task_id:django.request][exception.py:118][ERROR][Internal Server Error: /project_management/add_project_stage/]
Traceback (most recent call last):
  File "C:\Python\lib\site-packages\django\core\handlers\exception.py", line 35, in inner
    response = get_response(request)
  File "C:\Python\lib\site-packages\django\core\handlers\base.py", line 128, in _get_response
    response = self.process_exception_by_middleware(e, request)
  File "C:\Python\lib\site-packages\django\core\handlers\base.py", line 126, in _get_response
    response = wrapped_callback(request, *callback_args, **callback_kwargs)
  File "C:\Python\lib\site-packages\django\views\generic\base.py", line 69, in view
    return self.dispatch(request, *args, **kwargs)
  File "C:\Python\lib\site-packages\django\views\generic\base.py", line 89, in dispatch
    return handler(request, *args, **kwargs)
  File "C:\Python\bank\project_management\views.py", line 217, in post
    p_name = Project.objects.filter(id=project_id).first().p_name # 项目名称
AttributeError: 'NoneType' object has no attribute 'p_name'
[2018-12-29 16:50:55,261][Thread-43:12508][task_id:django.server][basehttp.py:124][ERROR]["POST /project_management/add_project_stage/ HTTP/1.1" 500 80420]
[2018-12-29 16:53:36,488][Thread-48:13980][task_id:django.request][exception.py:118][ERROR][Internal Server Error: /project_management/add_project_stage/]
Traceback (most recent call last):
  File "C:\Python\lib\site-packages\django\core\handlers\exception.py", line 35, in inner
    response = get_response(request)
  File "C:\Python\lib\site-packages\django\core\handlers\base.py", line 128, in _get_response
    response = self.process_exception_by_middleware(e, request)
  File "C:\Python\lib\site-packages\django\core\handlers\base.py", line 126, in _get_response
    response = wrapped_callback(request, *callback_args, **callback_kwargs)
  File "C:\Python\lib\site-packages\django\views\generic\base.py", line 69, in view
    return self.dispatch(request, *args, **kwargs)
  File "C:\Python\lib\site-packages\django\views\generic\base.py", line 89, in dispatch
    return handler(request, *args, **kwargs)
  File "C:\Python\bank\project_management\views.py", line 217, in post
    p_name = Project.objects.filter(id=project_id).first().p_name # 项目名称
AttributeError: 'NoneType' object has no attribute 'p_name'
[2018-12-29 16:53:36,533][Thread-48:13980][task_id:django.server][basehttp.py:124][ERROR]["POST /project_management/add_project_stage/ HTTP/1.1" 500 80420]
[2018-12-29 16:57:13,467][Thread-50:10356][task_id:django.request][exception.py:118][ERROR][Internal Server Error: /project_management/add_project_stage/]
Traceback (most recent call last):
  File "C:\Python\lib\site-packages\django\core\handlers\exception.py", line 35, in inner
    response = get_response(request)
  File "C:\Python\lib\site-packages\django\core\handlers\base.py", line 128, in _get_response
    response = self.process_exception_by_middleware(e, request)
  File "C:\Python\lib\site-packages\django\core\handlers\base.py", line 126, in _get_response
    response = wrapped_callback(request, *callback_args, **callback_kwargs)
  File "C:\Python\lib\site-packages\django\views\generic\base.py", line 69, in view
    return self.dispatch(request, *args, **kwargs)
  File "C:\Python\lib\site-packages\django\views\generic\base.py", line 89, in dispatch
    return handler(request, *args, **kwargs)
  File "C:\Python\bank\project_management\views.py", line 217, in post
    p_name = Project.objects.filter(id=project_id).first().p_name # 项目名称
AttributeError: 'NoneType' object has no attribute 'p_name'
[2018-12-29 16:57:13,512][Thread-50:10356][task_id:django.server][basehttp.py:124][ERROR]["POST /project_management/add_project_stage/ HTTP/1.1" 500 80417]
[2018-12-29 16:57:37,958][Thread-52:12324][task_id:django.request][exception.py:118][ERROR][Internal Server Error: /project_management/add_project_stage/]
Traceback (most recent call last):
  File "C:\Python\lib\site-packages\django\core\handlers\exception.py", line 35, in inner
    response = get_response(request)
  File "C:\Python\lib\site-packages\django\core\handlers\base.py", line 128, in _get_response
    response = self.process_exception_by_middleware(e, request)
  File "C:\Python\lib\site-packages\django\core\handlers\base.py", line 126, in _get_response
    response = wrapped_callback(request, *callback_args, **callback_kwargs)
  File "C:\Python\lib\site-packages\django\views\generic\base.py", line 69, in view
    return self.dispatch(request, *args, **kwargs)
  File "C:\Python\lib\site-packages\django\views\generic\base.py", line 89, in dispatch
    return handler(request, *args, **kwargs)
  File "C:\Python\bank\project_management\views.py", line 217, in post
    p_name = Project.objects.filter(id=project_id).first().p_name # 项目名称
AttributeError: 'NoneType' object has no attribute 'p_name'
[2018-12-29 16:57:38,002][Thread-52:12324][task_id:django.server][basehttp.py:124][ERROR]["POST /project_management/add_project_stage/ HTTP/1.1" 500 80424]
[2018-12-29 17:37:57,728][Thread-10:8524][task_id:django.server][basehttp.py:124][ERROR]["GET /system/operation_log/ HTTP/1.1" 500 59]
