[2018-12-27 09:58:55,854][Thread-342:13140][task_id:django.request][exception.py:118][ERROR][Internal Server Error: /project_management/add_project_stage/]
Traceback (most recent call last):
  File "C:\Python\lib\site-packages\django\core\handlers\exception.py", line 35, in inner
    response = get_response(request)
  File "C:\Python\lib\site-packages\django\core\handlers\base.py", line 128, in _get_response
    response = self.process_exception_by_middleware(e, request)
  File "C:\Python\lib\site-packages\django\core\handlers\base.py", line 126, in _get_response
    response = wrapped_callback(request, *callback_args, **callback_kwargs)
  File "C:\Python\lib\site-packages\django\views\generic\base.py", line 69, in view
    return self.dispatch(request, *args, **kwargs)
  File "C:\Python\lib\site-packages\django\views\generic\base.py", line 89, in dispatch
    return handler(request, *args, **kwargs)
  File "C:\Python\bank\project_management\views.py", line 91, in post
    d1 = Project.objects.get(id=pro_id)# 获取外键信息
  File "C:\Python\lib\site-packages\django\db\models\manager.py", line 82, in manager_method
    return getattr(self.get_queryset(), name)(*args, **kwargs)
  File "C:\Python\lib\site-packages\django\db\models\query.py", line 394, in get
    clone = self.filter(*args, **kwargs)
  File "C:\Python\lib\site-packages\django\db\models\query.py", line 836, in filter
    return self._filter_or_exclude(False, *args, **kwargs)
  File "C:\Python\lib\site-packages\django\db\models\query.py", line 854, in _filter_or_exclude
    clone.query.add_q(Q(*args, **kwargs))
  File "C:\Python\lib\site-packages\django\db\models\sql\query.py", line 1252, in add_q
    clause, _ = self._add_q(q_object, self.used_aliases)
  File "C:\Python\lib\site-packages\django\db\models\sql\query.py", line 1276, in _add_q
    split_subq=split_subq,
  File "C:\Python\lib\site-packages\django\db\models\sql\query.py", line 1214, in build_filter
    condition = self.build_lookup(lookups, col, value)
  File "C:\Python\lib\site-packages\django\db\models\sql\query.py", line 1084, in build_lookup
    lookup = lookup_class(lhs, rhs)
  File "C:\Python\lib\site-packages\django\db\models\lookups.py", line 18, in __init__
    self.rhs = self.get_prep_lookup()
  File "C:\Python\lib\site-packages\django\db\models\lookups.py", line 68, in get_prep_lookup
    return self.lhs.output_field.get_prep_value(self.rhs)
  File "C:\Python\lib\site-packages\django\db\models\fields\__init__.py", line 947, in get_prep_value
    return int(value)
ValueError: invalid literal for int() with base 10: ''
[2018-12-27 09:58:57,634][Thread-342:13140][task_id:django.server][basehttp.py:124][ERROR]["POST /project_management/add_project_stage/ HTTP/1.1" 500 129413]
[2018-12-27 11:19:36,695][Thread-191:12544][task_id:django.request][exception.py:118][ERROR][Internal Server Error: /project_management/add_project_stage/]
Traceback (most recent call last):
  File "C:\Python\lib\site-packages\django\core\handlers\exception.py", line 35, in inner
    response = get_response(request)
  File "C:\Python\lib\site-packages\django\core\handlers\base.py", line 128, in _get_response
    response = self.process_exception_by_middleware(e, request)
  File "C:\Python\lib\site-packages\django\core\handlers\base.py", line 126, in _get_response
    response = wrapped_callback(request, *callback_args, **callback_kwargs)
  File "C:\Python\lib\site-packages\django\views\generic\base.py", line 69, in view
    return self.dispatch(request, *args, **kwargs)
  File "C:\Python\lib\site-packages\django\views\generic\base.py", line 89, in dispatch
    return handler(request, *args, **kwargs)
  File "C:\Python\bank\project_management\views.py", line 91, in post
    d1 = Project.objects.get(id=pro_id)# 获取外键信息
  File "C:\Python\lib\site-packages\django\db\models\manager.py", line 82, in manager_method
    return getattr(self.get_queryset(), name)(*args, **kwargs)
  File "C:\Python\lib\site-packages\django\db\models\query.py", line 394, in get
    clone = self.filter(*args, **kwargs)
  File "C:\Python\lib\site-packages\django\db\models\query.py", line 836, in filter
    return self._filter_or_exclude(False, *args, **kwargs)
  File "C:\Python\lib\site-packages\django\db\models\query.py", line 854, in _filter_or_exclude
    clone.query.add_q(Q(*args, **kwargs))
  File "C:\Python\lib\site-packages\django\db\models\sql\query.py", line 1252, in add_q
    clause, _ = self._add_q(q_object, self.used_aliases)
  File "C:\Python\lib\site-packages\django\db\models\sql\query.py", line 1276, in _add_q
    split_subq=split_subq,
  File "C:\Python\lib\site-packages\django\db\models\sql\query.py", line 1214, in build_filter
    condition = self.build_lookup(lookups, col, value)
  File "C:\Python\lib\site-packages\django\db\models\sql\query.py", line 1084, in build_lookup
    lookup = lookup_class(lhs, rhs)
  File "C:\Python\lib\site-packages\django\db\models\lookups.py", line 18, in __init__
    self.rhs = self.get_prep_lookup()
  File "C:\Python\lib\site-packages\django\db\models\lookups.py", line 68, in get_prep_lookup
    return self.lhs.output_field.get_prep_value(self.rhs)
  File "C:\Python\lib\site-packages\django\db\models\fields\__init__.py", line 947, in get_prep_value
    return int(value)
ValueError: invalid literal for int() with base 10: ''
[2018-12-27 11:19:37,410][Thread-191:12544][task_id:django.server][basehttp.py:124][ERROR]["POST /project_management/add_project_stage/ HTTP/1.1" 500 129413]
[2018-12-27 11:20:06,417][Thread-199:4188][task_id:django.request][exception.py:118][ERROR][Internal Server Error: /project_management/add_project_stage/]
Traceback (most recent call last):
  File "C:\Python\lib\site-packages\django\core\handlers\exception.py", line 35, in inner
    response = get_response(request)
  File "C:\Python\lib\site-packages\django\core\handlers\base.py", line 128, in _get_response
    response = self.process_exception_by_middleware(e, request)
  File "C:\Python\lib\site-packages\django\core\handlers\base.py", line 126, in _get_response
    response = wrapped_callback(request, *callback_args, **callback_kwargs)
  File "C:\Python\lib\site-packages\django\views\generic\base.py", line 69, in view
    return self.dispatch(request, *args, **kwargs)
  File "C:\Python\lib\site-packages\django\views\generic\base.py", line 89, in dispatch
    return handler(request, *args, **kwargs)
  File "C:\Python\bank\project_management\views.py", line 91, in post
    d1 = Project.objects.get(id=pro_id)# 获取外键信息
  File "C:\Python\lib\site-packages\django\db\models\manager.py", line 82, in manager_method
    return getattr(self.get_queryset(), name)(*args, **kwargs)
  File "C:\Python\lib\site-packages\django\db\models\query.py", line 394, in get
    clone = self.filter(*args, **kwargs)
  File "C:\Python\lib\site-packages\django\db\models\query.py", line 836, in filter
    return self._filter_or_exclude(False, *args, **kwargs)
  File "C:\Python\lib\site-packages\django\db\models\query.py", line 854, in _filter_or_exclude
    clone.query.add_q(Q(*args, **kwargs))
  File "C:\Python\lib\site-packages\django\db\models\sql\query.py", line 1252, in add_q
    clause, _ = self._add_q(q_object, self.used_aliases)
  File "C:\Python\lib\site-packages\django\db\models\sql\query.py", line 1276, in _add_q
    split_subq=split_subq,
  File "C:\Python\lib\site-packages\django\db\models\sql\query.py", line 1214, in build_filter
    condition = self.build_lookup(lookups, col, value)
  File "C:\Python\lib\site-packages\django\db\models\sql\query.py", line 1084, in build_lookup
    lookup = lookup_class(lhs, rhs)
  File "C:\Python\lib\site-packages\django\db\models\lookups.py", line 18, in __init__
    self.rhs = self.get_prep_lookup()
  File "C:\Python\lib\site-packages\django\db\models\lookups.py", line 68, in get_prep_lookup
    return self.lhs.output_field.get_prep_value(self.rhs)
  File "C:\Python\lib\site-packages\django\db\models\fields\__init__.py", line 947, in get_prep_value
    return int(value)
ValueError: invalid literal for int() with base 10: ''
[2018-12-27 11:20:06,523][Thread-199:4188][task_id:django.server][basehttp.py:124][ERROR]["POST /project_management/add_project_stage/ HTTP/1.1" 500 129413]
[2018-12-27 11:21:18,820][Thread-205:6052][task_id:django.request][exception.py:118][ERROR][Internal Server Error: /project_management/add_project_stage/]
Traceback (most recent call last):
  File "C:\Python\lib\site-packages\django\core\handlers\exception.py", line 35, in inner
    response = get_response(request)
  File "C:\Python\lib\site-packages\django\core\handlers\base.py", line 128, in _get_response
    response = self.process_exception_by_middleware(e, request)
  File "C:\Python\lib\site-packages\django\core\handlers\base.py", line 126, in _get_response
    response = wrapped_callback(request, *callback_args, **callback_kwargs)
  File "C:\Python\lib\site-packages\django\views\generic\base.py", line 69, in view
    return self.dispatch(request, *args, **kwargs)
  File "C:\Python\lib\site-packages\django\views\generic\base.py", line 89, in dispatch
    return handler(request, *args, **kwargs)
  File "C:\Python\bank\project_management\views.py", line 91, in post
    d1 = Project.objects.get(id=pro_id)# 获取外键信息
  File "C:\Python\lib\site-packages\django\db\models\manager.py", line 82, in manager_method
    return getattr(self.get_queryset(), name)(*args, **kwargs)
  File "C:\Python\lib\site-packages\django\db\models\query.py", line 394, in get
    clone = self.filter(*args, **kwargs)
  File "C:\Python\lib\site-packages\django\db\models\query.py", line 836, in filter
    return self._filter_or_exclude(False, *args, **kwargs)
  File "C:\Python\lib\site-packages\django\db\models\query.py", line 854, in _filter_or_exclude
    clone.query.add_q(Q(*args, **kwargs))
  File "C:\Python\lib\site-packages\django\db\models\sql\query.py", line 1252, in add_q
    clause, _ = self._add_q(q_object, self.used_aliases)
  File "C:\Python\lib\site-packages\django\db\models\sql\query.py", line 1276, in _add_q
    split_subq=split_subq,
  File "C:\Python\lib\site-packages\django\db\models\sql\query.py", line 1214, in build_filter
    condition = self.build_lookup(lookups, col, value)
  File "C:\Python\lib\site-packages\django\db\models\sql\query.py", line 1084, in build_lookup
    lookup = lookup_class(lhs, rhs)
  File "C:\Python\lib\site-packages\django\db\models\lookups.py", line 18, in __init__
    self.rhs = self.get_prep_lookup()
  File "C:\Python\lib\site-packages\django\db\models\lookups.py", line 68, in get_prep_lookup
    return self.lhs.output_field.get_prep_value(self.rhs)
  File "C:\Python\lib\site-packages\django\db\models\fields\__init__.py", line 947, in get_prep_value
    return int(value)
ValueError: invalid literal for int() with base 10: ''
[2018-12-27 11:21:18,956][Thread-205:6052][task_id:django.server][basehttp.py:124][ERROR]["POST /project_management/add_project_stage/ HTTP/1.1" 500 129413]
[2018-12-27 11:21:28,062][Thread-213:9932][task_id:django.request][exception.py:118][ERROR][Internal Server Error: /project_management/add_project_stage/]
Traceback (most recent call last):
  File "C:\Python\lib\site-packages\django\core\handlers\exception.py", line 35, in inner
    response = get_response(request)
  File "C:\Python\lib\site-packages\django\core\handlers\base.py", line 128, in _get_response
    response = self.process_exception_by_middleware(e, request)
  File "C:\Python\lib\site-packages\django\core\handlers\base.py", line 126, in _get_response
    response = wrapped_callback(request, *callback_args, **callback_kwargs)
  File "C:\Python\lib\site-packages\django\views\generic\base.py", line 69, in view
    return self.dispatch(request, *args, **kwargs)
  File "C:\Python\lib\site-packages\django\views\generic\base.py", line 89, in dispatch
    return handler(request, *args, **kwargs)
  File "C:\Python\bank\project_management\views.py", line 91, in post
    d1 = Project.objects.get(id=pro_id)# 获取外键信息
  File "C:\Python\lib\site-packages\django\db\models\manager.py", line 82, in manager_method
    return getattr(self.get_queryset(), name)(*args, **kwargs)
  File "C:\Python\lib\site-packages\django\db\models\query.py", line 394, in get
    clone = self.filter(*args, **kwargs)
  File "C:\Python\lib\site-packages\django\db\models\query.py", line 836, in filter
    return self._filter_or_exclude(False, *args, **kwargs)
  File "C:\Python\lib\site-packages\django\db\models\query.py", line 854, in _filter_or_exclude
    clone.query.add_q(Q(*args, **kwargs))
  File "C:\Python\lib\site-packages\django\db\models\sql\query.py", line 1252, in add_q
    clause, _ = self._add_q(q_object, self.used_aliases)
  File "C:\Python\lib\site-packages\django\db\models\sql\query.py", line 1276, in _add_q
    split_subq=split_subq,
  File "C:\Python\lib\site-packages\django\db\models\sql\query.py", line 1214, in build_filter
    condition = self.build_lookup(lookups, col, value)
  File "C:\Python\lib\site-packages\django\db\models\sql\query.py", line 1084, in build_lookup
    lookup = lookup_class(lhs, rhs)
  File "C:\Python\lib\site-packages\django\db\models\lookups.py", line 18, in __init__
    self.rhs = self.get_prep_lookup()
  File "C:\Python\lib\site-packages\django\db\models\lookups.py", line 68, in get_prep_lookup
    return self.lhs.output_field.get_prep_value(self.rhs)
  File "C:\Python\lib\site-packages\django\db\models\fields\__init__.py", line 947, in get_prep_value
    return int(value)
ValueError: invalid literal for int() with base 10: ''
[2018-12-27 11:21:28,159][Thread-213:9932][task_id:django.server][basehttp.py:124][ERROR]["POST /project_management/add_project_stage/ HTTP/1.1" 500 129413]
[2018-12-27 11:21:50,344][Thread-247:2716][task_id:django.request][exception.py:118][ERROR][Internal Server Error: /project_management/add_project_stage/]
Traceback (most recent call last):
  File "C:\Python\lib\site-packages\django\core\handlers\exception.py", line 35, in inner
    response = get_response(request)
  File "C:\Python\lib\site-packages\django\core\handlers\base.py", line 128, in _get_response
    response = self.process_exception_by_middleware(e, request)
  File "C:\Python\lib\site-packages\django\core\handlers\base.py", line 126, in _get_response
    response = wrapped_callback(request, *callback_args, **callback_kwargs)
  File "C:\Python\lib\site-packages\django\views\generic\base.py", line 69, in view
    return self.dispatch(request, *args, **kwargs)
  File "C:\Python\lib\site-packages\django\views\generic\base.py", line 89, in dispatch
    return handler(request, *args, **kwargs)
  File "C:\Python\bank\project_management\views.py", line 91, in post
    d1 = Project.objects.get(id=pro_id)# 获取外键信息
  File "C:\Python\lib\site-packages\django\db\models\manager.py", line 82, in manager_method
    return getattr(self.get_queryset(), name)(*args, **kwargs)
  File "C:\Python\lib\site-packages\django\db\models\query.py", line 394, in get
    clone = self.filter(*args, **kwargs)
  File "C:\Python\lib\site-packages\django\db\models\query.py", line 836, in filter
    return self._filter_or_exclude(False, *args, **kwargs)
  File "C:\Python\lib\site-packages\django\db\models\query.py", line 854, in _filter_or_exclude
    clone.query.add_q(Q(*args, **kwargs))
  File "C:\Python\lib\site-packages\django\db\models\sql\query.py", line 1252, in add_q
    clause, _ = self._add_q(q_object, self.used_aliases)
  File "C:\Python\lib\site-packages\django\db\models\sql\query.py", line 1276, in _add_q
    split_subq=split_subq,
  File "C:\Python\lib\site-packages\django\db\models\sql\query.py", line 1214, in build_filter
    condition = self.build_lookup(lookups, col, value)
  File "C:\Python\lib\site-packages\django\db\models\sql\query.py", line 1084, in build_lookup
    lookup = lookup_class(lhs, rhs)
  File "C:\Python\lib\site-packages\django\db\models\lookups.py", line 18, in __init__
    self.rhs = self.get_prep_lookup()
  File "C:\Python\lib\site-packages\django\db\models\lookups.py", line 68, in get_prep_lookup
    return self.lhs.output_field.get_prep_value(self.rhs)
  File "C:\Python\lib\site-packages\django\db\models\fields\__init__.py", line 947, in get_prep_value
    return int(value)
ValueError: invalid literal for int() with base 10: ''
[2018-12-27 11:21:50,443][Thread-247:2716][task_id:django.server][basehttp.py:124][ERROR]["POST /project_management/add_project_stage/ HTTP/1.1" 500 129413]
[2018-12-27 11:21:55,240][Thread-253:11848][task_id:django.request][exception.py:118][ERROR][Internal Server Error: /project_management/add_project_stage/]
Traceback (most recent call last):
  File "C:\Python\lib\site-packages\django\core\handlers\exception.py", line 35, in inner
    response = get_response(request)
  File "C:\Python\lib\site-packages\django\core\handlers\base.py", line 128, in _get_response
    response = self.process_exception_by_middleware(e, request)
  File "C:\Python\lib\site-packages\django\core\handlers\base.py", line 126, in _get_response
    response = wrapped_callback(request, *callback_args, **callback_kwargs)
  File "C:\Python\lib\site-packages\django\views\generic\base.py", line 69, in view
    return self.dispatch(request, *args, **kwargs)
  File "C:\Python\lib\site-packages\django\views\generic\base.py", line 89, in dispatch
    return handler(request, *args, **kwargs)
  File "C:\Python\bank\project_management\views.py", line 91, in post
    d1 = Project.objects.get(id=pro_id)# 获取外键信息
  File "C:\Python\lib\site-packages\django\db\models\manager.py", line 82, in manager_method
    return getattr(self.get_queryset(), name)(*args, **kwargs)
  File "C:\Python\lib\site-packages\django\db\models\query.py", line 394, in get
    clone = self.filter(*args, **kwargs)
  File "C:\Python\lib\site-packages\django\db\models\query.py", line 836, in filter
    return self._filter_or_exclude(False, *args, **kwargs)
  File "C:\Python\lib\site-packages\django\db\models\query.py", line 854, in _filter_or_exclude
    clone.query.add_q(Q(*args, **kwargs))
  File "C:\Python\lib\site-packages\django\db\models\sql\query.py", line 1252, in add_q
    clause, _ = self._add_q(q_object, self.used_aliases)
  File "C:\Python\lib\site-packages\django\db\models\sql\query.py", line 1276, in _add_q
    split_subq=split_subq,
  File "C:\Python\lib\site-packages\django\db\models\sql\query.py", line 1214, in build_filter
    condition = self.build_lookup(lookups, col, value)
  File "C:\Python\lib\site-packages\django\db\models\sql\query.py", line 1084, in build_lookup
    lookup = lookup_class(lhs, rhs)
  File "C:\Python\lib\site-packages\django\db\models\lookups.py", line 18, in __init__
    self.rhs = self.get_prep_lookup()
  File "C:\Python\lib\site-packages\django\db\models\lookups.py", line 68, in get_prep_lookup
    return self.lhs.output_field.get_prep_value(self.rhs)
  File "C:\Python\lib\site-packages\django\db\models\fields\__init__.py", line 947, in get_prep_value
    return int(value)
ValueError: invalid literal for int() with base 10: ''
[2018-12-27 11:21:55,347][Thread-253:11848][task_id:django.server][basehttp.py:124][ERROR]["POST /project_management/add_project_stage/ HTTP/1.1" 500 129413]
[2018-12-27 11:26:58,877][Thread-313:11616][task_id:django.request][exception.py:118][ERROR][Internal Server Error: /project_management/add_project_stage/]
Traceback (most recent call last):
  File "C:\Python\lib\site-packages\django\core\handlers\exception.py", line 35, in inner
    response = get_response(request)
  File "C:\Python\lib\site-packages\django\core\handlers\base.py", line 128, in _get_response
    response = self.process_exception_by_middleware(e, request)
  File "C:\Python\lib\site-packages\django\core\handlers\base.py", line 126, in _get_response
    response = wrapped_callback(request, *callback_args, **callback_kwargs)
  File "C:\Python\lib\site-packages\django\views\generic\base.py", line 69, in view
    return self.dispatch(request, *args, **kwargs)
  File "C:\Python\lib\site-packages\django\views\generic\base.py", line 89, in dispatch
    return handler(request, *args, **kwargs)
  File "C:\Python\bank\project_management\views.py", line 91, in post
    d1 = Project.objects.get(id=pro_id)# 获取外键信息
  File "C:\Python\lib\site-packages\django\db\models\manager.py", line 82, in manager_method
    return getattr(self.get_queryset(), name)(*args, **kwargs)
  File "C:\Python\lib\site-packages\django\db\models\query.py", line 394, in get
    clone = self.filter(*args, **kwargs)
  File "C:\Python\lib\site-packages\django\db\models\query.py", line 836, in filter
    return self._filter_or_exclude(False, *args, **kwargs)
  File "C:\Python\lib\site-packages\django\db\models\query.py", line 854, in _filter_or_exclude
    clone.query.add_q(Q(*args, **kwargs))
  File "C:\Python\lib\site-packages\django\db\models\sql\query.py", line 1252, in add_q
    clause, _ = self._add_q(q_object, self.used_aliases)
  File "C:\Python\lib\site-packages\django\db\models\sql\query.py", line 1276, in _add_q
    split_subq=split_subq,
  File "C:\Python\lib\site-packages\django\db\models\sql\query.py", line 1214, in build_filter
    condition = self.build_lookup(lookups, col, value)
  File "C:\Python\lib\site-packages\django\db\models\sql\query.py", line 1084, in build_lookup
    lookup = lookup_class(lhs, rhs)
  File "C:\Python\lib\site-packages\django\db\models\lookups.py", line 18, in __init__
    self.rhs = self.get_prep_lookup()
  File "C:\Python\lib\site-packages\django\db\models\lookups.py", line 68, in get_prep_lookup
    return self.lhs.output_field.get_prep_value(self.rhs)
  File "C:\Python\lib\site-packages\django\db\models\fields\__init__.py", line 947, in get_prep_value
    return int(value)
ValueError: invalid literal for int() with base 10: ''
[2018-12-27 11:26:59,009][Thread-313:11616][task_id:django.server][basehttp.py:124][ERROR]["POST /project_management/add_project_stage/ HTTP/1.1" 500 129414]
[2018-12-27 12:11:39,287][Thread-342:9684][task_id:django.request][exception.py:118][ERROR][Internal Server Error: /project_management/add_project_stage/]
Traceback (most recent call last):
  File "C:\Python\lib\site-packages\django\core\handlers\exception.py", line 35, in inner
    response = get_response(request)
  File "C:\Python\lib\site-packages\django\core\handlers\base.py", line 128, in _get_response
    response = self.process_exception_by_middleware(e, request)
  File "C:\Python\lib\site-packages\django\core\handlers\base.py", line 126, in _get_response
    response = wrapped_callback(request, *callback_args, **callback_kwargs)
  File "C:\Python\lib\site-packages\django\views\generic\base.py", line 69, in view
    return self.dispatch(request, *args, **kwargs)
  File "C:\Python\lib\site-packages\django\views\generic\base.py", line 89, in dispatch
    return handler(request, *args, **kwargs)
  File "C:\Python\bank\project_management\views.py", line 91, in post
    d1 = Project.objects.get(id=pro_id)# 获取外键信息
  File "C:\Python\lib\site-packages\django\db\models\manager.py", line 82, in manager_method
    return getattr(self.get_queryset(), name)(*args, **kwargs)
  File "C:\Python\lib\site-packages\django\db\models\query.py", line 394, in get
    clone = self.filter(*args, **kwargs)
  File "C:\Python\lib\site-packages\django\db\models\query.py", line 836, in filter
    return self._filter_or_exclude(False, *args, **kwargs)
  File "C:\Python\lib\site-packages\django\db\models\query.py", line 854, in _filter_or_exclude
    clone.query.add_q(Q(*args, **kwargs))
  File "C:\Python\lib\site-packages\django\db\models\sql\query.py", line 1252, in add_q
    clause, _ = self._add_q(q_object, self.used_aliases)
  File "C:\Python\lib\site-packages\django\db\models\sql\query.py", line 1276, in _add_q
    split_subq=split_subq,
  File "C:\Python\lib\site-packages\django\db\models\sql\query.py", line 1214, in build_filter
    condition = self.build_lookup(lookups, col, value)
  File "C:\Python\lib\site-packages\django\db\models\sql\query.py", line 1084, in build_lookup
    lookup = lookup_class(lhs, rhs)
  File "C:\Python\lib\site-packages\django\db\models\lookups.py", line 18, in __init__
    self.rhs = self.get_prep_lookup()
  File "C:\Python\lib\site-packages\django\db\models\lookups.py", line 68, in get_prep_lookup
    return self.lhs.output_field.get_prep_value(self.rhs)
  File "C:\Python\lib\site-packages\django\db\models\fields\__init__.py", line 947, in get_prep_value
    return int(value)
ValueError: invalid literal for int() with base 10: ''
[2018-12-27 12:11:39,553][Thread-342:9684][task_id:django.server][basehttp.py:124][ERROR]["POST /project_management/add_project_stage/ HTTP/1.1" 500 129415]
[2018-12-27 12:18:57,472][Thread-375:3364][task_id:django.request][exception.py:118][ERROR][Internal Server Error: /project_management/add_project_stage/]
Traceback (most recent call last):
  File "C:\Python\lib\site-packages\django\core\handlers\exception.py", line 35, in inner
    response = get_response(request)
  File "C:\Python\lib\site-packages\django\core\handlers\base.py", line 128, in _get_response
    response = self.process_exception_by_middleware(e, request)
  File "C:\Python\lib\site-packages\django\core\handlers\base.py", line 126, in _get_response
    response = wrapped_callback(request, *callback_args, **callback_kwargs)
  File "C:\Python\lib\site-packages\django\views\generic\base.py", line 69, in view
    return self.dispatch(request, *args, **kwargs)
  File "C:\Python\lib\site-packages\django\views\generic\base.py", line 89, in dispatch
    return handler(request, *args, **kwargs)
  File "C:\Python\bank\project_management\views.py", line 91, in post
    d1 = Project.objects.get(id=pro_id)# 获取外键信息
  File "C:\Python\lib\site-packages\django\db\models\manager.py", line 82, in manager_method
    return getattr(self.get_queryset(), name)(*args, **kwargs)
  File "C:\Python\lib\site-packages\django\db\models\query.py", line 394, in get
    clone = self.filter(*args, **kwargs)
  File "C:\Python\lib\site-packages\django\db\models\query.py", line 836, in filter
    return self._filter_or_exclude(False, *args, **kwargs)
  File "C:\Python\lib\site-packages\django\db\models\query.py", line 854, in _filter_or_exclude
    clone.query.add_q(Q(*args, **kwargs))
  File "C:\Python\lib\site-packages\django\db\models\sql\query.py", line 1252, in add_q
    clause, _ = self._add_q(q_object, self.used_aliases)
  File "C:\Python\lib\site-packages\django\db\models\sql\query.py", line 1276, in _add_q
    split_subq=split_subq,
  File "C:\Python\lib\site-packages\django\db\models\sql\query.py", line 1214, in build_filter
    condition = self.build_lookup(lookups, col, value)
  File "C:\Python\lib\site-packages\django\db\models\sql\query.py", line 1084, in build_lookup
    lookup = lookup_class(lhs, rhs)
  File "C:\Python\lib\site-packages\django\db\models\lookups.py", line 18, in __init__
    self.rhs = self.get_prep_lookup()
  File "C:\Python\lib\site-packages\django\db\models\lookups.py", line 68, in get_prep_lookup
    return self.lhs.output_field.get_prep_value(self.rhs)
  File "C:\Python\lib\site-packages\django\db\models\fields\__init__.py", line 947, in get_prep_value
    return int(value)
ValueError: invalid literal for int() with base 10: ''
[2018-12-27 12:18:57,655][Thread-375:3364][task_id:django.server][basehttp.py:124][ERROR]["POST /project_management/add_project_stage/ HTTP/1.1" 500 129414]
[2018-12-27 12:22:08,244][Thread-418:12892][task_id:django.request][exception.py:118][ERROR][Internal Server Error: /project_management/add_project_stage/]
Traceback (most recent call last):
  File "C:\Python\lib\site-packages\django\core\handlers\exception.py", line 35, in inner
    response = get_response(request)
  File "C:\Python\lib\site-packages\django\core\handlers\base.py", line 128, in _get_response
    response = self.process_exception_by_middleware(e, request)
  File "C:\Python\lib\site-packages\django\core\handlers\base.py", line 126, in _get_response
    response = wrapped_callback(request, *callback_args, **callback_kwargs)
  File "C:\Python\lib\site-packages\django\views\generic\base.py", line 69, in view
    return self.dispatch(request, *args, **kwargs)
  File "C:\Python\lib\site-packages\django\views\generic\base.py", line 89, in dispatch
    return handler(request, *args, **kwargs)
  File "C:\Python\bank\project_management\views.py", line 91, in post
    d1 = Project.objects.get(id=pro_id)# 获取外键信息
  File "C:\Python\lib\site-packages\django\db\models\manager.py", line 82, in manager_method
    return getattr(self.get_queryset(), name)(*args, **kwargs)
  File "C:\Python\lib\site-packages\django\db\models\query.py", line 394, in get
    clone = self.filter(*args, **kwargs)
  File "C:\Python\lib\site-packages\django\db\models\query.py", line 836, in filter
    return self._filter_or_exclude(False, *args, **kwargs)
  File "C:\Python\lib\site-packages\django\db\models\query.py", line 854, in _filter_or_exclude
    clone.query.add_q(Q(*args, **kwargs))
  File "C:\Python\lib\site-packages\django\db\models\sql\query.py", line 1252, in add_q
    clause, _ = self._add_q(q_object, self.used_aliases)
  File "C:\Python\lib\site-packages\django\db\models\sql\query.py", line 1276, in _add_q
    split_subq=split_subq,
  File "C:\Python\lib\site-packages\django\db\models\sql\query.py", line 1214, in build_filter
    condition = self.build_lookup(lookups, col, value)
  File "C:\Python\lib\site-packages\django\db\models\sql\query.py", line 1084, in build_lookup
    lookup = lookup_class(lhs, rhs)
  File "C:\Python\lib\site-packages\django\db\models\lookups.py", line 18, in __init__
    self.rhs = self.get_prep_lookup()
  File "C:\Python\lib\site-packages\django\db\models\lookups.py", line 68, in get_prep_lookup
    return self.lhs.output_field.get_prep_value(self.rhs)
  File "C:\Python\lib\site-packages\django\db\models\fields\__init__.py", line 947, in get_prep_value
    return int(value)
ValueError: invalid literal for int() with base 10: ''
[2018-12-27 12:22:08,345][Thread-418:12892][task_id:django.server][basehttp.py:124][ERROR]["POST /project_management/add_project_stage/ HTTP/1.1" 500 129413]
[2018-12-27 12:22:39,692][Thread-444:2504][task_id:django.request][exception.py:118][ERROR][Internal Server Error: /project_management/add_project_stage/]
Traceback (most recent call last):
  File "C:\Python\lib\site-packages\django\core\handlers\exception.py", line 35, in inner
    response = get_response(request)
  File "C:\Python\lib\site-packages\django\core\handlers\base.py", line 128, in _get_response
    response = self.process_exception_by_middleware(e, request)
  File "C:\Python\lib\site-packages\django\core\handlers\base.py", line 126, in _get_response
    response = wrapped_callback(request, *callback_args, **callback_kwargs)
  File "C:\Python\lib\site-packages\django\views\generic\base.py", line 69, in view
    return self.dispatch(request, *args, **kwargs)
  File "C:\Python\lib\site-packages\django\views\generic\base.py", line 89, in dispatch
    return handler(request, *args, **kwargs)
  File "C:\Python\bank\project_management\views.py", line 91, in post
    d1 = Project.objects.get(id=pro_id)# 获取外键信息
  File "C:\Python\lib\site-packages\django\db\models\manager.py", line 82, in manager_method
    return getattr(self.get_queryset(), name)(*args, **kwargs)
  File "C:\Python\lib\site-packages\django\db\models\query.py", line 394, in get
    clone = self.filter(*args, **kwargs)
  File "C:\Python\lib\site-packages\django\db\models\query.py", line 836, in filter
    return self._filter_or_exclude(False, *args, **kwargs)
  File "C:\Python\lib\site-packages\django\db\models\query.py", line 854, in _filter_or_exclude
    clone.query.add_q(Q(*args, **kwargs))
  File "C:\Python\lib\site-packages\django\db\models\sql\query.py", line 1252, in add_q
    clause, _ = self._add_q(q_object, self.used_aliases)
  File "C:\Python\lib\site-packages\django\db\models\sql\query.py", line 1276, in _add_q
    split_subq=split_subq,
  File "C:\Python\lib\site-packages\django\db\models\sql\query.py", line 1214, in build_filter
    condition = self.build_lookup(lookups, col, value)
  File "C:\Python\lib\site-packages\django\db\models\sql\query.py", line 1084, in build_lookup
    lookup = lookup_class(lhs, rhs)
  File "C:\Python\lib\site-packages\django\db\models\lookups.py", line 18, in __init__
    self.rhs = self.get_prep_lookup()
  File "C:\Python\lib\site-packages\django\db\models\lookups.py", line 68, in get_prep_lookup
    return self.lhs.output_field.get_prep_value(self.rhs)
  File "C:\Python\lib\site-packages\django\db\models\fields\__init__.py", line 947, in get_prep_value
    return int(value)
ValueError: invalid literal for int() with base 10: ''
[2018-12-27 12:22:39,785][Thread-444:2504][task_id:django.server][basehttp.py:124][ERROR]["POST /project_management/add_project_stage/ HTTP/1.1" 500 129413]
[2018-12-27 12:29:33,331][Thread-513:4776][task_id:django.request][exception.py:118][ERROR][Internal Server Error: /project_management/add_project_stage/]
Traceback (most recent call last):
  File "C:\Python\lib\site-packages\django\core\handlers\exception.py", line 35, in inner
    response = get_response(request)
  File "C:\Python\lib\site-packages\django\core\handlers\base.py", line 128, in _get_response
    response = self.process_exception_by_middleware(e, request)
  File "C:\Python\lib\site-packages\django\core\handlers\base.py", line 126, in _get_response
    response = wrapped_callback(request, *callback_args, **callback_kwargs)
  File "C:\Python\lib\site-packages\django\views\generic\base.py", line 69, in view
    return self.dispatch(request, *args, **kwargs)
  File "C:\Python\lib\site-packages\django\views\generic\base.py", line 89, in dispatch
    return handler(request, *args, **kwargs)
  File "C:\Python\bank\project_management\views.py", line 91, in post
    d1 = Project.objects.get(id=pro_id)# 获取外键信息
  File "C:\Python\lib\site-packages\django\db\models\manager.py", line 82, in manager_method
    return getattr(self.get_queryset(), name)(*args, **kwargs)
  File "C:\Python\lib\site-packages\django\db\models\query.py", line 403, in get
    self.model._meta.object_name
project_management.models.DoesNotExist: Project matching query does not exist.
[2018-12-27 12:29:33,400][Thread-513:4776][task_id:django.server][basehttp.py:124][ERROR]["POST /project_management/add_project_stage/ HTTP/1.1" 500 87655]
[2018-12-27 12:32:10,276][Thread-549:13116][task_id:django.request][exception.py:118][ERROR][Internal Server Error: /project_management/add_project_stage/]
Traceback (most recent call last):
  File "C:\Python\lib\site-packages\django\core\handlers\exception.py", line 35, in inner
    response = get_response(request)
  File "C:\Python\lib\site-packages\django\core\handlers\base.py", line 128, in _get_response
    response = self.process_exception_by_middleware(e, request)
  File "C:\Python\lib\site-packages\django\core\handlers\base.py", line 126, in _get_response
    response = wrapped_callback(request, *callback_args, **callback_kwargs)
  File "C:\Python\lib\site-packages\django\views\generic\base.py", line 69, in view
    return self.dispatch(request, *args, **kwargs)
  File "C:\Python\lib\site-packages\django\views\generic\base.py", line 89, in dispatch
    return handler(request, *args, **kwargs)
  File "C:\Python\bank\project_management\views.py", line 91, in post
    d1 = Project.objects.get(id=pro_id)# 获取外键信息
  File "C:\Python\lib\site-packages\django\db\models\manager.py", line 82, in manager_method
    return getattr(self.get_queryset(), name)(*args, **kwargs)
  File "C:\Python\lib\site-packages\django\db\models\query.py", line 403, in get
    self.model._meta.object_name
project_management.models.DoesNotExist: Project matching query does not exist.
[2018-12-27 12:32:10,337][Thread-549:13116][task_id:django.server][basehttp.py:124][ERROR]["POST /project_management/add_project_stage/ HTTP/1.1" 500 87646]
[2018-12-27 12:33:09,537][Thread-583:1376][task_id:django.request][exception.py:118][ERROR][Internal Server Error: /project_management/add_project_stage/]
Traceback (most recent call last):
  File "C:\Python\lib\site-packages\django\core\handlers\exception.py", line 35, in inner
    response = get_response(request)
  File "C:\Python\lib\site-packages\django\core\handlers\base.py", line 128, in _get_response
    response = self.process_exception_by_middleware(e, request)
  File "C:\Python\lib\site-packages\django\core\handlers\base.py", line 126, in _get_response
    response = wrapped_callback(request, *callback_args, **callback_kwargs)
  File "C:\Python\lib\site-packages\django\views\generic\base.py", line 69, in view
    return self.dispatch(request, *args, **kwargs)
  File "C:\Python\lib\site-packages\django\views\generic\base.py", line 89, in dispatch
    return handler(request, *args, **kwargs)
  File "C:\Python\bank\project_management\views.py", line 91, in post
    d1 = Project.objects.get(id=pro_id)# 获取外键信息
  File "C:\Python\lib\site-packages\django\db\models\manager.py", line 82, in manager_method
    return getattr(self.get_queryset(), name)(*args, **kwargs)
  File "C:\Python\lib\site-packages\django\db\models\query.py", line 403, in get
    self.model._meta.object_name
project_management.models.DoesNotExist: Project matching query does not exist.
[2018-12-27 12:33:09,613][Thread-583:1376][task_id:django.server][basehttp.py:124][ERROR]["POST /project_management/add_project_stage/ HTTP/1.1" 500 87647]
[2018-12-27 12:33:30,605][Thread-627:12332][task_id:django.request][exception.py:118][ERROR][Internal Server Error: /project_management/add_project_stage/]
Traceback (most recent call last):
  File "C:\Python\lib\site-packages\django\core\handlers\exception.py", line 35, in inner
    response = get_response(request)
  File "C:\Python\lib\site-packages\django\core\handlers\base.py", line 128, in _get_response
    response = self.process_exception_by_middleware(e, request)
  File "C:\Python\lib\site-packages\django\core\handlers\base.py", line 126, in _get_response
    response = wrapped_callback(request, *callback_args, **callback_kwargs)
  File "C:\Python\lib\site-packages\django\views\generic\base.py", line 69, in view
    return self.dispatch(request, *args, **kwargs)
  File "C:\Python\lib\site-packages\django\views\generic\base.py", line 89, in dispatch
    return handler(request, *args, **kwargs)
  File "C:\Python\bank\project_management\views.py", line 91, in post
    d1 = Project.objects.get(id=pro_id)# 获取外键信息
  File "C:\Python\lib\site-packages\django\db\models\manager.py", line 82, in manager_method
    return getattr(self.get_queryset(), name)(*args, **kwargs)
  File "C:\Python\lib\site-packages\django\db\models\query.py", line 403, in get
    self.model._meta.object_name
project_management.models.DoesNotExist: Project matching query does not exist.
[2018-12-27 12:33:30,681][Thread-627:12332][task_id:django.server][basehttp.py:124][ERROR]["POST /project_management/add_project_stage/ HTTP/1.1" 500 87649]
[2018-12-27 12:35:40,897][Thread-677:5124][task_id:django.request][exception.py:118][ERROR][Internal Server Error: /project_management/add_project_stage/]
Traceback (most recent call last):
  File "C:\Python\lib\site-packages\django\core\handlers\exception.py", line 35, in inner
    response = get_response(request)
  File "C:\Python\lib\site-packages\django\core\handlers\base.py", line 128, in _get_response
    response = self.process_exception_by_middleware(e, request)
  File "C:\Python\lib\site-packages\django\core\handlers\base.py", line 126, in _get_response
    response = wrapped_callback(request, *callback_args, **callback_kwargs)
  File "C:\Python\lib\site-packages\django\views\generic\base.py", line 69, in view
    return self.dispatch(request, *args, **kwargs)
  File "C:\Python\lib\site-packages\django\views\generic\base.py", line 89, in dispatch
    return handler(request, *args, **kwargs)
  File "C:\Python\bank\project_management\views.py", line 91, in post
    d1 = Project.objects.get(id=pro_id)# 获取外键信息
  File "C:\Python\lib\site-packages\django\db\models\manager.py", line 82, in manager_method
    return getattr(self.get_queryset(), name)(*args, **kwargs)
  File "C:\Python\lib\site-packages\django\db\models\query.py", line 403, in get
    self.model._meta.object_name
project_management.models.DoesNotExist: Project matching query does not exist.
[2018-12-27 12:35:40,973][Thread-677:5124][task_id:django.server][basehttp.py:124][ERROR]["POST /project_management/add_project_stage/ HTTP/1.1" 500 87647]
[2018-12-27 12:36:37,272][Thread-708:8104][task_id:django.request][exception.py:118][ERROR][Internal Server Error: /project_management/add_project_stage/]
Traceback (most recent call last):
  File "C:\Python\lib\site-packages\django\core\handlers\exception.py", line 35, in inner
    response = get_response(request)
  File "C:\Python\lib\site-packages\django\core\handlers\base.py", line 128, in _get_response
    response = self.process_exception_by_middleware(e, request)
  File "C:\Python\lib\site-packages\django\core\handlers\base.py", line 126, in _get_response
    response = wrapped_callback(request, *callback_args, **callback_kwargs)
  File "C:\Python\lib\site-packages\django\views\generic\base.py", line 69, in view
    return self.dispatch(request, *args, **kwargs)
  File "C:\Python\lib\site-packages\django\views\generic\base.py", line 89, in dispatch
    return handler(request, *args, **kwargs)
  File "C:\Python\bank\project_management\views.py", line 91, in post
    d1 = Project.objects.get(id=pro_id)# 获取外键信息
  File "C:\Python\lib\site-packages\django\db\models\manager.py", line 82, in manager_method
    return getattr(self.get_queryset(), name)(*args, **kwargs)
  File "C:\Python\lib\site-packages\django\db\models\query.py", line 403, in get
    self.model._meta.object_name
project_management.models.DoesNotExist: Project matching query does not exist.
[2018-12-27 12:36:37,339][Thread-708:8104][task_id:django.server][basehttp.py:124][ERROR]["POST /project_management/add_project_stage/ HTTP/1.1" 500 87648]
[2018-12-27 12:41:00,689][Thread-743:7640][task_id:django.request][exception.py:118][ERROR][Internal Server Error: /project_management/add_project_stage/]
Traceback (most recent call last):
  File "C:\Python\lib\site-packages\django\core\handlers\exception.py", line 35, in inner
    response = get_response(request)
  File "C:\Python\lib\site-packages\django\core\handlers\base.py", line 128, in _get_response
    response = self.process_exception_by_middleware(e, request)
  File "C:\Python\lib\site-packages\django\core\handlers\base.py", line 126, in _get_response
    response = wrapped_callback(request, *callback_args, **callback_kwargs)
  File "C:\Python\lib\site-packages\django\views\generic\base.py", line 69, in view
    return self.dispatch(request, *args, **kwargs)
  File "C:\Python\lib\site-packages\django\views\generic\base.py", line 89, in dispatch
    return handler(request, *args, **kwargs)
  File "C:\Python\bank\project_management\views.py", line 91, in post
    d1 = Project.objects.get(id=pro_id)# 获取外键信息
  File "C:\Python\lib\site-packages\django\db\models\manager.py", line 82, in manager_method
    return getattr(self.get_queryset(), name)(*args, **kwargs)
  File "C:\Python\lib\site-packages\django\db\models\query.py", line 403, in get
    self.model._meta.object_name
project_management.models.DoesNotExist: Project matching query does not exist.
[2018-12-27 12:41:00,746][Thread-743:7640][task_id:django.server][basehttp.py:124][ERROR]["POST /project_management/add_project_stage/ HTTP/1.1" 500 87647]
[2018-12-27 12:44:39,921][Thread-774:8756][task_id:django.request][exception.py:118][ERROR][Internal Server Error: /project_management/add_project_stage/]
Traceback (most recent call last):
  File "C:\Python\lib\site-packages\django\core\handlers\exception.py", line 35, in inner
    response = get_response(request)
  File "C:\Python\lib\site-packages\django\core\handlers\base.py", line 128, in _get_response
    response = self.process_exception_by_middleware(e, request)
  File "C:\Python\lib\site-packages\django\core\handlers\base.py", line 126, in _get_response
    response = wrapped_callback(request, *callback_args, **callback_kwargs)
  File "C:\Python\lib\site-packages\django\views\generic\base.py", line 69, in view
    return self.dispatch(request, *args, **kwargs)
  File "C:\Python\lib\site-packages\django\views\generic\base.py", line 89, in dispatch
    return handler(request, *args, **kwargs)
  File "C:\Python\bank\project_management\views.py", line 91, in post
    d1 = Project.objects.get(id=pro_id)# 获取外键信息
  File "C:\Python\lib\site-packages\django\db\models\manager.py", line 82, in manager_method
    return getattr(self.get_queryset(), name)(*args, **kwargs)
  File "C:\Python\lib\site-packages\django\db\models\query.py", line 403, in get
    self.model._meta.object_name
project_management.models.DoesNotExist: Project matching query does not exist.
[2018-12-27 12:44:39,991][Thread-774:8756][task_id:django.server][basehttp.py:124][ERROR]["POST /project_management/add_project_stage/ HTTP/1.1" 500 87647]
[2018-12-27 12:50:35,399][Thread-812:4396][task_id:django.request][exception.py:118][ERROR][Internal Server Error: /project_management/add_project_stage/]
Traceback (most recent call last):
  File "C:\Python\lib\site-packages\django\core\handlers\exception.py", line 35, in inner
    response = get_response(request)
  File "C:\Python\lib\site-packages\django\core\handlers\base.py", line 128, in _get_response
    response = self.process_exception_by_middleware(e, request)
  File "C:\Python\lib\site-packages\django\core\handlers\base.py", line 126, in _get_response
    response = wrapped_callback(request, *callback_args, **callback_kwargs)
  File "C:\Python\lib\site-packages\django\views\generic\base.py", line 69, in view
    return self.dispatch(request, *args, **kwargs)
  File "C:\Python\lib\site-packages\django\views\generic\base.py", line 89, in dispatch
    return handler(request, *args, **kwargs)
  File "C:\Python\bank\project_management\views.py", line 91, in post
    d1 = Project.objects.get(id=pro_id)# 获取外键信息
  File "C:\Python\lib\site-packages\django\db\models\manager.py", line 82, in manager_method
    return getattr(self.get_queryset(), name)(*args, **kwargs)
  File "C:\Python\lib\site-packages\django\db\models\query.py", line 403, in get
    self.model._meta.object_name
project_management.models.DoesNotExist: Project matching query does not exist.
[2018-12-27 12:50:35,453][Thread-812:4396][task_id:django.server][basehttp.py:124][ERROR]["POST /project_management/add_project_stage/ HTTP/1.1" 500 87646]
[2018-12-27 13:03:23,788][Thread-1026:1352][task_id:django.request][exception.py:118][ERROR][Internal Server Error: /project_management/add_project_stage/]
Traceback (most recent call last):
  File "C:\Python\lib\site-packages\django\core\handlers\exception.py", line 35, in inner
    response = get_response(request)
  File "C:\Python\lib\site-packages\django\core\handlers\base.py", line 128, in _get_response
    response = self.process_exception_by_middleware(e, request)
  File "C:\Python\lib\site-packages\django\core\handlers\base.py", line 126, in _get_response
    response = wrapped_callback(request, *callback_args, **callback_kwargs)
  File "C:\Python\lib\site-packages\django\views\generic\base.py", line 69, in view
    return self.dispatch(request, *args, **kwargs)
  File "C:\Python\lib\site-packages\django\views\generic\base.py", line 89, in dispatch
    return handler(request, *args, **kwargs)
  File "C:\Python\bank\project_management\views.py", line 91, in post
    d1 = Project.objects.get(id=pro_id)# 获取外键信息
  File "C:\Python\lib\site-packages\django\db\models\manager.py", line 82, in manager_method
    return getattr(self.get_queryset(), name)(*args, **kwargs)
  File "C:\Python\lib\site-packages\django\db\models\query.py", line 403, in get
    self.model._meta.object_name
project_management.models.DoesNotExist: Project matching query does not exist.
[2018-12-27 13:03:23,856][Thread-1026:1352][task_id:django.server][basehttp.py:124][ERROR]["POST /project_management/add_project_stage/ HTTP/1.1" 500 87646]
[2018-12-27 13:04:31,950][Thread-1069:6096][task_id:django.request][exception.py:118][ERROR][Internal Server Error: /project_management/add_project_stage/]
Traceback (most recent call last):
  File "C:\Python\lib\site-packages\django\core\handlers\exception.py", line 35, in inner
    response = get_response(request)
  File "C:\Python\lib\site-packages\django\core\handlers\base.py", line 128, in _get_response
    response = self.process_exception_by_middleware(e, request)
  File "C:\Python\lib\site-packages\django\core\handlers\base.py", line 126, in _get_response
    response = wrapped_callback(request, *callback_args, **callback_kwargs)
  File "C:\Python\lib\site-packages\django\views\generic\base.py", line 69, in view
    return self.dispatch(request, *args, **kwargs)
  File "C:\Python\lib\site-packages\django\views\generic\base.py", line 89, in dispatch
    return handler(request, *args, **kwargs)
  File "C:\Python\bank\project_management\views.py", line 91, in post
    d1 = Project.objects.get(id=pro_id)# 获取外键信息
  File "C:\Python\lib\site-packages\django\db\models\manager.py", line 82, in manager_method
    return getattr(self.get_queryset(), name)(*args, **kwargs)
  File "C:\Python\lib\site-packages\django\db\models\query.py", line 403, in get
    self.model._meta.object_name
project_management.models.DoesNotExist: Project matching query does not exist.
[2018-12-27 13:04:32,003][Thread-1069:6096][task_id:django.server][basehttp.py:124][ERROR]["POST /project_management/add_project_stage/ HTTP/1.1" 500 87646]
[2018-12-27 13:21:07,771][Thread-1079:4244][task_id:django.request][exception.py:118][ERROR][Internal Server Error: /project_management/add_project_stage/]
Traceback (most recent call last):
  File "C:\Python\lib\site-packages\django\core\handlers\exception.py", line 35, in inner
    response = get_response(request)
  File "C:\Python\lib\site-packages\django\core\handlers\base.py", line 128, in _get_response
    response = self.process_exception_by_middleware(e, request)
  File "C:\Python\lib\site-packages\django\core\handlers\base.py", line 126, in _get_response
    response = wrapped_callback(request, *callback_args, **callback_kwargs)
  File "C:\Python\lib\site-packages\django\views\generic\base.py", line 69, in view
    return self.dispatch(request, *args, **kwargs)
  File "C:\Python\lib\site-packages\django\views\generic\base.py", line 89, in dispatch
    return handler(request, *args, **kwargs)
  File "C:\Python\bank\project_management\views.py", line 106, in post
    projects.save()
  File "C:\Python\lib\site-packages\django\db\models\base.py", line 729, in save
    force_update=force_update, update_fields=update_fields)
  File "C:\Python\lib\site-packages\django\db\models\base.py", line 759, in save_base
    updated = self._save_table(raw, cls, force_insert, force_update, using, update_fields)
  File "C:\Python\lib\site-packages\django\db\models\base.py", line 842, in _save_table
    result = self._do_insert(cls._base_manager, using, fields, update_pk, raw)
  File "C:\Python\lib\site-packages\django\db\models\base.py", line 880, in _do_insert
    using=using, raw=raw)
  File "C:\Python\lib\site-packages\django\db\models\manager.py", line 82, in manager_method
    return getattr(self.get_queryset(), name)(*args, **kwargs)
  File "C:\Python\lib\site-packages\django\db\models\query.py", line 1125, in _insert
    return query.get_compiler(using=using).execute_sql(return_id)
  File "C:\Python\lib\site-packages\django\db\models\sql\compiler.py", line 1279, in execute_sql
    for sql, params in self.as_sql():
  File "C:\Python\lib\site-packages\django\db\models\sql\compiler.py", line 1232, in as_sql
    for obj in self.query.objs
  File "C:\Python\lib\site-packages\django\db\models\sql\compiler.py", line 1232, in <listcomp>
    for obj in self.query.objs
  File "C:\Python\lib\site-packages\django\db\models\sql\compiler.py", line 1231, in <listcomp>
    [self.prepare_value(field, self.pre_save_val(field, obj)) for field in fields]
  File "C:\Python\lib\site-packages\django\db\models\sql\compiler.py", line 1171, in prepare_value
    value = field.get_db_prep_save(value, connection=self.connection)
  File "C:\Python\lib\site-packages\django\db\models\fields\__init__.py", line 767, in get_db_prep_save
    return self.get_db_prep_value(value, connection=connection, prepared=False)
  File "C:\Python\lib\site-packages\django\db\models\fields\__init__.py", line 1276, in get_db_prep_value
    value = self.get_prep_value(value)
  File "C:\Python\lib\site-packages\django\db\models\fields\__init__.py", line 1271, in get_prep_value
    return self.to_python(value)
  File "C:\Python\lib\site-packages\django\db\models\fields\__init__.py", line 1246, in to_python
    params={'value': value},
django.core.exceptions.ValidationError: ['’2‘ 必须为合法的日期格式，请使用 YYYY-MM-DD 格式。']
[2018-12-27 13:21:07,984][Thread-1079:4244][task_id:django.server][basehttp.py:124][ERROR]["POST /project_management/add_project_stage/ HTTP/1.1" 500 151069]
[2018-12-27 13:39:06,005][Thread-1148:8104][task_id:django.request][exception.py:118][ERROR][Internal Server Error: /project_management/add_project_stage/]
Traceback (most recent call last):
  File "C:\Python\lib\site-packages\django\core\handlers\exception.py", line 35, in inner
    response = get_response(request)
  File "C:\Python\lib\site-packages\django\core\handlers\base.py", line 128, in _get_response
    response = self.process_exception_by_middleware(e, request)
  File "C:\Python\lib\site-packages\django\core\handlers\base.py", line 126, in _get_response
    response = wrapped_callback(request, *callback_args, **callback_kwargs)
  File "C:\Python\lib\site-packages\django\views\generic\base.py", line 69, in view
    return self.dispatch(request, *args, **kwargs)
  File "C:\Python\lib\site-packages\django\views\generic\base.py", line 89, in dispatch
    return handler(request, *args, **kwargs)
  File "C:\Python\bank\project_management\views.py", line 106, in post
    projects.save()
  File "C:\Python\lib\site-packages\django\db\models\base.py", line 729, in save
    force_update=force_update, update_fields=update_fields)
  File "C:\Python\lib\site-packages\django\db\models\base.py", line 759, in save_base
    updated = self._save_table(raw, cls, force_insert, force_update, using, update_fields)
  File "C:\Python\lib\site-packages\django\db\models\base.py", line 842, in _save_table
    result = self._do_insert(cls._base_manager, using, fields, update_pk, raw)
  File "C:\Python\lib\site-packages\django\db\models\base.py", line 880, in _do_insert
    using=using, raw=raw)
  File "C:\Python\lib\site-packages\django\db\models\manager.py", line 82, in manager_method
    return getattr(self.get_queryset(), name)(*args, **kwargs)
  File "C:\Python\lib\site-packages\django\db\models\query.py", line 1125, in _insert
    return query.get_compiler(using=using).execute_sql(return_id)
  File "C:\Python\lib\site-packages\django\db\models\sql\compiler.py", line 1279, in execute_sql
    for sql, params in self.as_sql():
  File "C:\Python\lib\site-packages\django\db\models\sql\compiler.py", line 1232, in as_sql
    for obj in self.query.objs
  File "C:\Python\lib\site-packages\django\db\models\sql\compiler.py", line 1232, in <listcomp>
    for obj in self.query.objs
  File "C:\Python\lib\site-packages\django\db\models\sql\compiler.py", line 1231, in <listcomp>
    [self.prepare_value(field, self.pre_save_val(field, obj)) for field in fields]
  File "C:\Python\lib\site-packages\django\db\models\sql\compiler.py", line 1171, in prepare_value
    value = field.get_db_prep_save(value, connection=self.connection)
  File "C:\Python\lib\site-packages\django\db\models\fields\__init__.py", line 767, in get_db_prep_save
    return self.get_db_prep_value(value, connection=connection, prepared=False)
  File "C:\Python\lib\site-packages\django\db\models\fields\__init__.py", line 1276, in get_db_prep_value
    value = self.get_prep_value(value)
  File "C:\Python\lib\site-packages\django\db\models\fields\__init__.py", line 1271, in get_prep_value
    return self.to_python(value)
  File "C:\Python\lib\site-packages\django\db\models\fields\__init__.py", line 1246, in to_python
    params={'value': value},
django.core.exceptions.ValidationError: ['’2018-03-‘ 必须为合法的日期格式，请使用 YYYY-MM-DD 格式。']
[2018-12-27 13:39:06,123][Thread-1148:8104][task_id:django.server][basehttp.py:124][ERROR]["POST /project_management/add_project_stage/ HTTP/1.1" 500 151172]
[2018-12-27 13:39:37,755][Thread-1164:6028][task_id:django.request][exception.py:118][ERROR][Internal Server Error: /project_management/add_project_stage/]
Traceback (most recent call last):
  File "C:\Python\lib\site-packages\django\core\handlers\exception.py", line 35, in inner
    response = get_response(request)
  File "C:\Python\lib\site-packages\django\core\handlers\base.py", line 128, in _get_response
    response = self.process_exception_by_middleware(e, request)
  File "C:\Python\lib\site-packages\django\core\handlers\base.py", line 126, in _get_response
    response = wrapped_callback(request, *callback_args, **callback_kwargs)
  File "C:\Python\lib\site-packages\django\views\generic\base.py", line 69, in view
    return self.dispatch(request, *args, **kwargs)
  File "C:\Python\lib\site-packages\django\views\generic\base.py", line 89, in dispatch
    return handler(request, *args, **kwargs)
  File "C:\Python\bank\project_management\views.py", line 106, in post
    projects.save()
  File "C:\Python\lib\site-packages\django\db\models\base.py", line 729, in save
    force_update=force_update, update_fields=update_fields)
  File "C:\Python\lib\site-packages\django\db\models\base.py", line 759, in save_base
    updated = self._save_table(raw, cls, force_insert, force_update, using, update_fields)
  File "C:\Python\lib\site-packages\django\db\models\base.py", line 842, in _save_table
    result = self._do_insert(cls._base_manager, using, fields, update_pk, raw)
  File "C:\Python\lib\site-packages\django\db\models\base.py", line 880, in _do_insert
    using=using, raw=raw)
  File "C:\Python\lib\site-packages\django\db\models\manager.py", line 82, in manager_method
    return getattr(self.get_queryset(), name)(*args, **kwargs)
  File "C:\Python\lib\site-packages\django\db\models\query.py", line 1125, in _insert
    return query.get_compiler(using=using).execute_sql(return_id)
  File "C:\Python\lib\site-packages\django\db\models\sql\compiler.py", line 1279, in execute_sql
    for sql, params in self.as_sql():
  File "C:\Python\lib\site-packages\django\db\models\sql\compiler.py", line 1232, in as_sql
    for obj in self.query.objs
  File "C:\Python\lib\site-packages\django\db\models\sql\compiler.py", line 1232, in <listcomp>
    for obj in self.query.objs
  File "C:\Python\lib\site-packages\django\db\models\sql\compiler.py", line 1231, in <listcomp>
    [self.prepare_value(field, self.pre_save_val(field, obj)) for field in fields]
  File "C:\Python\lib\site-packages\django\db\models\sql\compiler.py", line 1171, in prepare_value
    value = field.get_db_prep_save(value, connection=self.connection)
  File "C:\Python\lib\site-packages\django\db\models\fields\__init__.py", line 767, in get_db_prep_save
    return self.get_db_prep_value(value, connection=connection, prepared=False)
  File "C:\Python\lib\site-packages\django\db\models\fields\__init__.py", line 1276, in get_db_prep_value
    value = self.get_prep_value(value)
  File "C:\Python\lib\site-packages\django\db\models\fields\__init__.py", line 1271, in get_prep_value
    return self.to_python(value)
  File "C:\Python\lib\site-packages\django\db\models\fields\__init__.py", line 1246, in to_python
    params={'value': value},
django.core.exceptions.ValidationError: ['’2‘ 必须为合法的日期格式，请使用 YYYY-MM-DD 格式。']
[2018-12-27 13:39:37,867][Thread-1164:6028][task_id:django.server][basehttp.py:124][ERROR]["POST /project_management/add_project_stage/ HTTP/1.1" 500 151067]
[2018-12-27 13:42:07,156][Thread-1200:9264][task_id:django.request][exception.py:118][ERROR][Internal Server Error: /project_management/add_project_stage/]
Traceback (most recent call last):
  File "C:\Python\lib\site-packages\django\core\handlers\exception.py", line 35, in inner
    response = get_response(request)
  File "C:\Python\lib\site-packages\django\core\handlers\base.py", line 128, in _get_response
    response = self.process_exception_by_middleware(e, request)
  File "C:\Python\lib\site-packages\django\core\handlers\base.py", line 126, in _get_response
    response = wrapped_callback(request, *callback_args, **callback_kwargs)
  File "C:\Python\lib\site-packages\django\views\generic\base.py", line 69, in view
    return self.dispatch(request, *args, **kwargs)
  File "C:\Python\lib\site-packages\django\views\generic\base.py", line 89, in dispatch
    return handler(request, *args, **kwargs)
  File "C:\Python\bank\project_management\views.py", line 106, in post
    projects.save()
  File "C:\Python\lib\site-packages\django\db\models\base.py", line 729, in save
    force_update=force_update, update_fields=update_fields)
  File "C:\Python\lib\site-packages\django\db\models\base.py", line 759, in save_base
    updated = self._save_table(raw, cls, force_insert, force_update, using, update_fields)
  File "C:\Python\lib\site-packages\django\db\models\base.py", line 842, in _save_table
    result = self._do_insert(cls._base_manager, using, fields, update_pk, raw)
  File "C:\Python\lib\site-packages\django\db\models\base.py", line 880, in _do_insert
    using=using, raw=raw)
  File "C:\Python\lib\site-packages\django\db\models\manager.py", line 82, in manager_method
    return getattr(self.get_queryset(), name)(*args, **kwargs)
  File "C:\Python\lib\site-packages\django\db\models\query.py", line 1125, in _insert
    return query.get_compiler(using=using).execute_sql(return_id)
  File "C:\Python\lib\site-packages\django\db\models\sql\compiler.py", line 1279, in execute_sql
    for sql, params in self.as_sql():
  File "C:\Python\lib\site-packages\django\db\models\sql\compiler.py", line 1232, in as_sql
    for obj in self.query.objs
  File "C:\Python\lib\site-packages\django\db\models\sql\compiler.py", line 1232, in <listcomp>
    for obj in self.query.objs
  File "C:\Python\lib\site-packages\django\db\models\sql\compiler.py", line 1231, in <listcomp>
    [self.prepare_value(field, self.pre_save_val(field, obj)) for field in fields]
  File "C:\Python\lib\site-packages\django\db\models\sql\compiler.py", line 1171, in prepare_value
    value = field.get_db_prep_save(value, connection=self.connection)
  File "C:\Python\lib\site-packages\django\db\models\fields\__init__.py", line 767, in get_db_prep_save
    return self.get_db_prep_value(value, connection=connection, prepared=False)
  File "C:\Python\lib\site-packages\django\db\models\fields\__init__.py", line 1276, in get_db_prep_value
    value = self.get_prep_value(value)
  File "C:\Python\lib\site-packages\django\db\models\fields\__init__.py", line 1271, in get_prep_value
    return self.to_python(value)
  File "C:\Python\lib\site-packages\django\db\models\fields\__init__.py", line 1246, in to_python
    params={'value': value},
django.core.exceptions.ValidationError: ['’2‘ 必须为合法的日期格式，请使用 YYYY-MM-DD 格式。']
[2018-12-27 13:42:07,312][Thread-1200:9264][task_id:django.server][basehttp.py:124][ERROR]["POST /project_management/add_project_stage/ HTTP/1.1" 500 151066]
[2018-12-27 13:46:57,525][Thread-1235:1348][task_id:django.request][exception.py:118][ERROR][Internal Server Error: /project_management/add_project_stage/]
Traceback (most recent call last):
  File "C:\Python\lib\site-packages\django\core\handlers\exception.py", line 35, in inner
    response = get_response(request)
  File "C:\Python\lib\site-packages\django\core\handlers\base.py", line 128, in _get_response
    response = self.process_exception_by_middleware(e, request)
  File "C:\Python\lib\site-packages\django\core\handlers\base.py", line 126, in _get_response
    response = wrapped_callback(request, *callback_args, **callback_kwargs)
  File "C:\Python\lib\site-packages\django\views\generic\base.py", line 69, in view
    return self.dispatch(request, *args, **kwargs)
  File "C:\Python\lib\site-packages\django\views\generic\base.py", line 89, in dispatch
    return handler(request, *args, **kwargs)
  File "C:\Python\bank\project_management\views.py", line 106, in post
    projects.save()
  File "C:\Python\lib\site-packages\django\db\models\base.py", line 729, in save
    force_update=force_update, update_fields=update_fields)
  File "C:\Python\lib\site-packages\django\db\models\base.py", line 759, in save_base
    updated = self._save_table(raw, cls, force_insert, force_update, using, update_fields)
  File "C:\Python\lib\site-packages\django\db\models\base.py", line 842, in _save_table
    result = self._do_insert(cls._base_manager, using, fields, update_pk, raw)
  File "C:\Python\lib\site-packages\django\db\models\base.py", line 880, in _do_insert
    using=using, raw=raw)
  File "C:\Python\lib\site-packages\django\db\models\manager.py", line 82, in manager_method
    return getattr(self.get_queryset(), name)(*args, **kwargs)
  File "C:\Python\lib\site-packages\django\db\models\query.py", line 1125, in _insert
    return query.get_compiler(using=using).execute_sql(return_id)
  File "C:\Python\lib\site-packages\django\db\models\sql\compiler.py", line 1279, in execute_sql
    for sql, params in self.as_sql():
  File "C:\Python\lib\site-packages\django\db\models\sql\compiler.py", line 1232, in as_sql
    for obj in self.query.objs
  File "C:\Python\lib\site-packages\django\db\models\sql\compiler.py", line 1232, in <listcomp>
    for obj in self.query.objs
  File "C:\Python\lib\site-packages\django\db\models\sql\compiler.py", line 1231, in <listcomp>
    [self.prepare_value(field, self.pre_save_val(field, obj)) for field in fields]
  File "C:\Python\lib\site-packages\django\db\models\sql\compiler.py", line 1171, in prepare_value
    value = field.get_db_prep_save(value, connection=self.connection)
  File "C:\Python\lib\site-packages\django\db\models\fields\__init__.py", line 767, in get_db_prep_save
    return self.get_db_prep_value(value, connection=connection, prepared=False)
  File "C:\Python\lib\site-packages\django\db\models\fields\__init__.py", line 1276, in get_db_prep_value
    value = self.get_prep_value(value)
  File "C:\Python\lib\site-packages\django\db\models\fields\__init__.py", line 1271, in get_prep_value
    return self.to_python(value)
  File "C:\Python\lib\site-packages\django\db\models\fields\__init__.py", line 1246, in to_python
    params={'value': value},
django.core.exceptions.ValidationError: ['’2‘ 必须为合法的日期格式，请使用 YYYY-MM-DD 格式。']
[2018-12-27 13:46:57,635][Thread-1235:1348][task_id:django.server][basehttp.py:124][ERROR]["POST /project_management/add_project_stage/ HTTP/1.1" 500 151069]
[2018-12-27 13:50:34,900][Thread-1315:4804][task_id:django.request][exception.py:118][ERROR][Internal Server Error: /project_management/add_project/]
Traceback (most recent call last):
  File "C:\Python\lib\site-packages\django\core\handlers\exception.py", line 35, in inner
    response = get_response(request)
  File "C:\Python\lib\site-packages\django\core\handlers\base.py", line 128, in _get_response
    response = self.process_exception_by_middleware(e, request)
  File "C:\Python\lib\site-packages\django\core\handlers\base.py", line 126, in _get_response
    response = wrapped_callback(request, *callback_args, **callback_kwargs)
  File "C:\Python\lib\site-packages\django\views\generic\base.py", line 69, in view
    return self.dispatch(request, *args, **kwargs)
  File "C:\Python\lib\site-packages\django\views\generic\base.py", line 89, in dispatch
    return handler(request, *args, **kwargs)
  File "C:\Python\bank\project_management\views.py", line 76, in post
    projects.save()
  File "C:\Python\lib\site-packages\django\db\models\base.py", line 729, in save
    force_update=force_update, update_fields=update_fields)
  File "C:\Python\lib\site-packages\django\db\models\base.py", line 759, in save_base
    updated = self._save_table(raw, cls, force_insert, force_update, using, update_fields)
  File "C:\Python\lib\site-packages\django\db\models\base.py", line 842, in _save_table
    result = self._do_insert(cls._base_manager, using, fields, update_pk, raw)
  File "C:\Python\lib\site-packages\django\db\models\base.py", line 880, in _do_insert
    using=using, raw=raw)
  File "C:\Python\lib\site-packages\django\db\models\manager.py", line 82, in manager_method
    return getattr(self.get_queryset(), name)(*args, **kwargs)
  File "C:\Python\lib\site-packages\django\db\models\query.py", line 1125, in _insert
    return query.get_compiler(using=using).execute_sql(return_id)
  File "C:\Python\lib\site-packages\django\db\models\sql\compiler.py", line 1279, in execute_sql
    for sql, params in self.as_sql():
  File "C:\Python\lib\site-packages\django\db\models\sql\compiler.py", line 1232, in as_sql
    for obj in self.query.objs
  File "C:\Python\lib\site-packages\django\db\models\sql\compiler.py", line 1232, in <listcomp>
    for obj in self.query.objs
  File "C:\Python\lib\site-packages\django\db\models\sql\compiler.py", line 1231, in <listcomp>
    [self.prepare_value(field, self.pre_save_val(field, obj)) for field in fields]
  File "C:\Python\lib\site-packages\django\db\models\sql\compiler.py", line 1171, in prepare_value
    value = field.get_db_prep_save(value, connection=self.connection)
  File "C:\Python\lib\site-packages\django\db\models\fields\__init__.py", line 767, in get_db_prep_save
    return self.get_db_prep_value(value, connection=connection, prepared=False)
  File "C:\Python\lib\site-packages\django\db\models\fields\__init__.py", line 1276, in get_db_prep_value
    value = self.get_prep_value(value)
  File "C:\Python\lib\site-packages\django\db\models\fields\__init__.py", line 1271, in get_prep_value
    return self.to_python(value)
  File "C:\Python\lib\site-packages\django\db\models\fields\__init__.py", line 1246, in to_python
    params={'value': value},
django.core.exceptions.ValidationError: ['’‘ 必须为合法的日期格式，请使用 YYYY-MM-DD 格式。']
[2018-12-27 13:50:34,987][Thread-1315:4804][task_id:django.server][basehttp.py:124][ERROR]["POST /project_management/add_project/ HTTP/1.1" 500 149511]
[2018-12-27 13:50:49,031][Thread-1321:10824][task_id:django.request][exception.py:118][ERROR][Internal Server Error: /project_management/add_project_stage/]
Traceback (most recent call last):
  File "C:\Python\lib\site-packages\django\core\handlers\exception.py", line 35, in inner
    response = get_response(request)
  File "C:\Python\lib\site-packages\django\core\handlers\base.py", line 128, in _get_response
    response = self.process_exception_by_middleware(e, request)
  File "C:\Python\lib\site-packages\django\core\handlers\base.py", line 126, in _get_response
    response = wrapped_callback(request, *callback_args, **callback_kwargs)
  File "C:\Python\lib\site-packages\django\views\generic\base.py", line 69, in view
    return self.dispatch(request, *args, **kwargs)
  File "C:\Python\lib\site-packages\django\views\generic\base.py", line 89, in dispatch
    return handler(request, *args, **kwargs)
  File "C:\Python\bank\project_management\views.py", line 91, in post
    d1 = Project.objects.get(id=pro_id)# 获取外键信息
  File "C:\Python\lib\site-packages\django\db\models\manager.py", line 82, in manager_method
    return getattr(self.get_queryset(), name)(*args, **kwargs)
  File "C:\Python\lib\site-packages\django\db\models\query.py", line 403, in get
    self.model._meta.object_name
project_management.models.DoesNotExist: Project matching query does not exist.
[2018-12-27 13:50:49,092][Thread-1321:10824][task_id:django.server][basehttp.py:124][ERROR]["POST /project_management/add_project_stage/ HTTP/1.1" 500 87521]
